Workbook
Name Slicer_Reporting_Period_Name: #N/A
Name Slicer_Reporting_unit_name: #N/A
Name Slicer_Scope: #N/A
Name Slicer_Scope_Category: #N/A

Sheet hierarchy
A1: Name | B1: Parent Name | C1: Reporting Unit Type | D1: Open Date | E1: Close Date | F1: Country | G1: Sub-region | H1: Region | I1: State | J1: Postcode | K1: Latitude | L1: Longitude | M1: Viewers | N1: Data Managers | O1: Approvers | P1: Column1
A2: Asia Pacific | B2: Top of Hierarchy | C2: Region | D2: 36526 | E2: 31/12/2100 | H2: Asia | M2: jrohde.env@gmail.com | P2: 3279
A3: Europe | B3: Top of Hierarchy | C3: Region | D3: 36526 | E3: 31/12/2100 | H3: Europe | M3: jrohde.env@gmail.com | P3: 3278
A4: Middle East / Africa | B4: Top of Hierarchy | C4: Region | D4: 36526 | E4: 31/12/2100 | H4: Africa | M4: jrohde.env@gmail.com | P4: 3280
A5: North America | B5: Top of Hierarchy | C5: Region | D5: 36526 | E5: 31/12/2100 | H5: Americas | M5: jrohde.env@gmail.com | P5: 3276
A6: South America | B6: Top of Hierarchy | C6: Region | D6: 36526 | E6: 31/12/2100 | H6: Americas | M6: jrohde.env@gmail.com | P6: 3277
A7: Vantage_Granollers | B7: Europe | C7: Labratory | D7: 44197 | E7: 31/12/2022 | F7: Spain | G7: Southern Europe | H7: Europe | P7: 3300
A8: Vantage_South Africa | B8: Middle East / Africa | C8: Labratory | D8: 44197 | E8: 31/12/2022 | F8: South Africa | G8: Sub-Saharan Africa | H8: Africa | O8: jordyn.dean@anthesisgroup.com | P8: 3313
A9: Vantage_Chicago | B9: North America | C9: Labratory | D9: 44197 | E9: 31/12/2022 | F9: United States of America | G9: Northern America | H9: Americas | I9: IL | J9: 60609 | P9: 3294
A10: Vantage_Dateland | B10: North America | C10: Labratory | D10: 44197 | E10: 31/12/2022 | F10: United States of America | G10: Northern America | H10: Americas | I10: AZ | J10: 85333 | P10: 3296
A11: Vantage_Argentina Farm (Agrinsa) | B11: South America | C11: Labratory | D11: 44197 | E11: 31/12/2022 | F11: Argentina | G11: Latin America and the Caribbean | H11: Americas | P11: 3290
A12: Vantage_Shanghai | B12: Asia Pacific | C12: Warehouse | D12: 44197 | E12: 31/12/2022 | F12: China | G12: Eastern Asia | H12: Asia | P12: 3312
A13: Vantage_Linden | B13: North America | C13: Warehouse | D13: 44197 | E13: 31/12/2022 | F13: United States of America | G13: Northern America | H13: Americas | I13: NJ | J13: 7036 | P13: 3306
A14: Vantage_Tlalnepantla de Baz | B14: North America | C14: Warehouse | D14: 44197 | E14: 31/12/2022 | F14: Mexico | G14: Latin America and the Caribbean | H14: Americas | P14: 3314
A15: Vantage_Mumbai | B15: Asia Pacific | C15: Office | D15: 44197 | E15: 31/12/2022 | F15: India | G15: Southern Asia | H15: Asia | P15: 3307
A16: Vantage_Les Borges | B16: Europe | C16: Office | D16: 44197 | E16: 31/12/2022 | F16: Spain | G16: Southern Europe | H16: Europe | P16: 3303
A17: Vantage_Carnegie | B17: North America | C17: Office | D17: 44197 | E17: 31/12/2022 | F17: United States of America | G17: Northern America | H17: Americas | I17: PA | J17: 15106 | P17: 3293
A18: Vantage_Deerfield | B18: North America | C18: Office | D18: 44197 | E18: 31/12/2022 | F18: United States of America | G18: Northern America | H18: Americas | I18: IL | J18: 60015 | P18: 3297
A19: Vantage_Englewood | B19: North America | C19: Office | D19: 44197 | E19: 31/12/2022 | F19: United States of America | G19: Northern America | H19: Americas | I19: OH | P19: 3298
A20: Vantage_Fairfield | B20: North America | C20: Office | D20: 44197 | E20: 31/12/2022 | F20: United States of America | G20: Northern America | H20: Americas | I20: NJ | J20: 7004 | P20: 3299
A21: Vantage_Gurnee | B21: North America | C21: Office | D21: 44197 | E21: 31/12/2022 | F21: United States of America | G21: Northern America | H21: Americas | I21: IL | P21: 3302
A22: Vantage_Pittsburgh | B22: North America | C22: Office | D22: 44197 | E22: 31/12/2022 | F22: United States of America | G22: Northern America | H22: Americas | I22: PA | J22: 15205 | P22: 3309
A23: Vantage_Tucson | B23: North America | C23: Office | D23: 44197 | E23: 31/12/2022 | F23: United States of America | G23: Northern America | H23: Americas | I23: AZ | P23: 3315
A24: Vantage_Warren | B24: North America | C24: Office | D24: 44197 | E24: 31/12/2022 | F24: United States of America | G24: Northern America | H24: Americas | I24: NJ | J24: 7059 | P24: 3316
A25: Vantage_Bogotá | B25: South America | C25: Office | D25: 44197 | E25: 31/12/2022 | F25: Colombia | G25: Latin America and the Caribbean | H25: Americas | P25: 3291
A26: Vantage_Lima | B26: South America | C26: Office | D26: 44197 | E26: 31/12/2022 | F26: Peru | G26: Latin America and the Caribbean | H26: Americas | P26: 3305
A27: Vantage_Delta | B27: North America | C27: Factory | D27: 44562 | E27: 15/10/2022 | F27: United States of America | G27: Northern America | H27: Americas | I27: CO | P27: 8698
A28: Vantage_Buenos Aires | B28: South America | C28: Factory | D28: 44197 | E28: 31/12/2022 | F28: Argentina | G28: Latin America and the Caribbean | H28: Americas | P28: 3292
A29: Vantage_Paris | B29: Europe | C29: Unspecified Facility Type | D29: 44197 | E29: 31/12/2022 | F29: France | G29: Western Europe | H29: Europe | P29: 3308
A30: Vantage_Costa_Rica | B30: North America | C30: Unspecified Facility Type | D30: 44197 | E30: 31/12/2022 | F30: Costa Rica | G30: Latin America and the Caribbean | H30: Americas | P30: 3295
A31: Vantage_Guatemala City | B31: South America | C31: Unspecified Facility Type | D31: 44197 | E31: 31/12/2022 | F31: Guatemala | G31: Latin America and the Caribbean | H31: Americas | P31: 3301
A32: Vantage_Santiago | B32: South America | C32: Unspecified Facility Type | D32: 44197 | E32: 31/12/2022 | F32: Chile | G32: Latin America and the Caribbean | H32: Americas | P32: 3310
A33: Vantage_Sao Paulo | B33: South America | C33: Unspecified Facility Type | D33: 44197 | E33: 31/12/2022 | F33: Brazil | G33: Latin America and the Caribbean | H33: Americas | P33: 3311
A34: Vantage_Leuna | B34: Europe | C34: Office (with heat & steam) | D34: 44197 | E34: 31/12/2022 | F34: Germany | G34: Western Europe | H34: Europe | P34: 3304
A35: Top of Hierarchy | C35: Organisation | P35: 9410
A36: Scope 3 Inventory | B36: Top of Hierarchy | C36: Scope 3 Inventory | D36: 31/01/1900 | E36: 31/12/2099 | P36: 22402
A37: Category 2 (Capital Goods) | B37: Scope 3 Inventory | C37: Category 2 (Capital Goods) | D37: 31/01/1900 | E37: 31/12/2099 | F37: United States of America | G37: Northern America | H37: Americas | P37: 22405
A38: Category 4 (Upstream Transportation and Distribution) | B38: Scope 3 Inventory | C38: Category 4 (Upstream Transportation and Distribution) | D38: 31/01/1900 | E38: 31/12/2099 | F38: United States of America | G38: Northern America | H38: Americas | P38: 22406
A39: Category 6 (Business Travel) | B39: Scope 3 Inventory | C39: Category 6 (Business Travel) | D39: 31/01/1900 | E39: 31/12/2099 | F39: United States of America | G39: Northern America | H39: Americas | P39: 22404
A40: Category 5 (Waste Generated in Operations) | B40: Scope 3 Inventory | C40: Category 5 (Waste Generated in Operations) | D40: 31/01/1900 | E40: 31/12/2099 | F40: United States of America | G40: Northern America | H40: Americas | P40: 22407
...

Sheet data
A1: ID2 | B1: Reporting Unit Name | C1: Reporting Period Name | D1: Activity Group | E1: Start Period | F1: End Period | G1: Activity | H1: Quantity | I1: Unit | J1: Data Quality | K1: User | L1: Created Date | M1: Calculation Status | N1: Calculation Date | O1: Note | P1: Evidence | Q1: Column1 | R1: Column2 | S1: Column3
C2: 1676931 | D2: Top of Hierarchy > Scope 3 Inventory | E2: FY22 (Jan. 1, 2022 - Dec. 31, 2022) | F2: 12. End-of-life treatment of sold products | G2: 01-Oct-22 | H2: 31-Dec-22 | I2: 12. End-of-life treatment of sold products | J2: 113738.1 | K2: metric tonnes | L2: Estimated | M2: Daniella Giardetti | N2: 03-Aug-23, 19:32 | P2: Calculated | Q2: 03-Aug-23, 19:32
C3: 1676920 | D3: Top of Hierarchy > Scope 3 Inventory | E3: FY22 (Jan. 1, 2022 - Dec. 31, 2022) | F3: 1. Purchased goods and services | G3: 01-Jan-22 | H3: 31-Dec-22 | I3: 1. Purchased goods and services | J3: 805776.03 | K3: metric tonnes | L3: Estimated | M3: Daniella Giardetti | N3: 03-Aug-23, 19:29 | P3: Calculated | Q3: 08-Aug-23, 19:56
C4: 1676924 | D4: Top of Hierarchy > Scope 3 Inventory | E4: FY22 (Jan. 1, 2022 - Dec. 31, 2022) | F4: 2. Capital goods | G4: 01-Jan-22 | H4: 31-Dec-22 | I4: 2. Capital goods | J4: 2257.37 | K4: metric tonnes | L4: Estimated | M4: Daniella Giardetti | N4: 03-Aug-23, 19:30 | P4: Calculated | Q4: 08-Aug-23, 19:56
C5: 1676929 | D5: Top of Hierarchy > Scope 3 Inventory | E5: FY22 (Jan. 1, 2022 - Dec. 31, 2022) | F5: 4. Upstream transportation and distribution | G5: 01-Jan-22 | H5: 31-Dec-22 | I5: 4. Upstream transportation and distribution | J5: 22199.47 | K5: metric tonnes | L5: Estimated | M5: Daniella Giardetti | N5: 03-Aug-23, 19:31 | P5: Calculated | Q5: 03-Aug-23, 19:31
C6: 1676927 | D6: Top of Hierarchy > Scope 3 Inventory | E6: FY22 (Jan. 1, 2022 - Dec. 31, 2022) | F6: 5. Waste generated in operations | G6: 01-Jan-22 | H6: 31-Dec-22 | I6: 5. Waste generated in operations | J6: 4060.75 | K6: metric tonnes | L6: Estimated | M6: Daniella Giardetti | N6: 03-Aug-23, 19:31 | P6: Calculated | Q6: 08-Aug-23, 19:57
C7: 1676933 | D7: Top of Hierarchy > Scope 3 Inventory | E7: FY22 (Jan. 1, 2022 - Dec. 31, 2022) | F7: 11. Use of sold products | G7: 01-Jan-22 | H7: 31-Dec-22 | I7: 11. Use of sold products | J7: 2622.48 | K7: metric tonnes | L7: Estimated | M7: Daniella Giardetti | N7: 03-Aug-23, 19:32 | P7: Calculated | Q7: 03-Aug-23, 19:32
C8: 1676938 | D8: Top of Hierarchy > Scope 3 Inventory | E8: FY21 (Jan. 1, 2021 - Dec. 31, 2021) | F8: 2. Capital goods | G8: 01-Oct-21 | H8: 31-Dec-21 | I8: 2. Capital goods | J8: 1836.64 | K8: metric tonnes | L8: Estimated | M8: Daniella Giardetti | N8: 03-Aug-23, 20:01 | P8: Calculated | Q8: 08-Aug-23, 19:58
C9: 1677403 | D9: Top of Hierarchy > Scope 3 Inventory | E9: FY21 (Jan. 1, 2021 - Dec. 31, 2021) | F9: 4. Upstream transportation and distribution | G9: 01-Oct-21 | H9: 31-Dec-21 | I9: 4. Upstream transportation and distribution | J9: 17021.04 | K9: metric tonnes | L9: Estimated | M9: Daniella Giardetti | N9: 04-Aug-23, 16:27 | P9: Calculated | Q9: 08-Aug-23, 19:59
C10: 1677405 | D10: Top of Hierarchy > Scope 3 Inventory | E10: FY21 (Jan. 1, 2021 - Dec. 31, 2021) | F10: 5. Waste generated in operations | G10: 01-Oct-21 | H10: 31-Dec-21 | I10: 5. Waste generated in operations | J10: 2522.25 | K10: metric tonnes | L10: Estimated | M10: Daniella Giardetti | N10: 04-Aug-23, 16:28 | P10: Calculated | Q10: 08-Aug-23, 19:58
C11: 1677407 | D11: Top of Hierarchy > Scope 3 Inventory | E11: FY21 (Jan. 1, 2021 - Dec. 31, 2021) | F11: 11. Use of sold products | G11: 01-Oct-21 | H11: 31-Dec-21 | I11: 11. Use of sold products | J11: 740.94 | K11: metric tonnes | L11: Estimated | M11: Daniella Giardetti | N11: 04-Aug-23, 16:28 | P11: Calculated | Q11: 04-Aug-23, 16:28
C12: 1677409 | D12: Top of Hierarchy > Scope 3 Inventory | E12: FY21 (Jan. 1, 2021 - Dec. 31, 2021) | F12: 12. End-of-life treatment of sold products | G12: 01-Oct-21 | H12: 31-Dec-21 | I12: 12. End-of-life treatment of sold products | J12: 105039.06 | K12: metric tonnes | L12: Estimated | M12: Daniella Giardetti | N12: 04-Aug-23, 16:29 | P12: Calculated | Q12: 04-Aug-23, 16:29
C13: 1676922 | D13: Top of Hierarchy > Scope 3 Inventory | E13: FY21 (Jan. 1, 2021 - Dec. 31, 2021) | F13: 1. Purchased goods and services | G13: 01-Jan-21 | H13: 31-Dec-21 | I13: 1. Purchased goods and services | J13: 741930.79 | K13: metric tonnes | L13: Estimated | M13: Daniella Giardetti | N13: 03-Aug-23, 19:29 | P13: Calculated | Q13: 08-Aug-23, 19:58
C14: 294640 | D14: Top of Hierarchy > Middle East / Africa > Vantage_South Africa | E14: FY22 (Jan. 1, 2022 - Dec. 31, 2022) | F14: Electricity (non-renewable) | G14: 01-Jan-22 | H14: 31-Dec-22 | I14: Electricity (non-renewable) | J14: 41510.999 | K14: Kilowatt hours | L14: Actual Data | M14: Frank Greene | N14: 09-May-23, 16:29 | P14: Calculated | Q14: 20-Jul-23, 00:40 | R14: landlord invoice | S14: Vantage South Africa 2022 Sustainability Electricity and Water Data.pdf
C15: 1590451 | D15: Top of Hierarchy > Middle East / Africa > Vantage_South Africa | E15: FY22 (Jan. 1, 2022 - Dec. 31, 2022) | F15: Refrigerant gasses | G15: 01-Jan-22 | H15: 31-Dec-22 | I15: R-134A | J15: 4.8781995 | K15: kilograms | L15: Estimated | M15: Daniella Giardetti | N15: 25-Jul-23, 17:50 | P15: Calculated | Q15: 25-Jul-23, 17:50 | R15: Estimated from square footage. Assumed R134a.
C16: 294642 | D16: Top of Hierarchy > Middle East / Africa > Vantage_South Africa | E16: FY22 (Jan. 1, 2022 - Dec. 31, 2022) | F16: Gaseous fuel activities | G16: 01-Jan-22 | H16: 31-Dec-22 | I16: LPG | J16: 228 | K16: kilograms | L16: Estimated | M16: Frank Greene | N16: 09-May-23, 17:15 | P16: Calculated | Q16: 20-Jul-23, 00:40 | R16: Estimated based off last year
C17: 4963 | D17: Top of Hierarchy > Middle East / Africa > Vantage_South Africa | E17: FY21 (Jan. 1, 2021 - Dec. 31, 2021) | F17: Electricity (non-renewable) | G17: 01-Jan-21 | H17: 31-Dec-21 | I17: Electricity (non-renewable) | J17: 43695.568 | K17: Kilowatt hours | L17: Actual Data | M17: Frank Greene | N17: 27-Feb-23, 16:27 | P17: Calculated | Q17: 03-Aug-23, 20:20 | S17: Vantage South Africa 2021 Sustainability Electricity and Water Data, South Africa electricity and natural gas accounting (2).xlsx
C18: 5048 | D18: Top of Hierarchy > Middle East / Africa > Vantage_South Africa | E18: FY21 (Jan. 1, 2021 - Dec. 31, 2021) | F18: Refrigerant gasses | G18: 01-Jan-21 | H18: 31-Dec-21 | I18: HFC-134a | J18: 4.8782 | K18: kilograms | L18: Estimated | M18: Jordyn Dean | N18: 27-Feb-23, 16:27 | P18: Calculated | Q18: 20-Jul-23, 00:40
C19: 1230929 | D19: Top of Hierarchy > Middle East / Africa > Vantage_South Africa | E19: FY21 (Jan. 1, 2021 - Dec. 31, 2021) | F19: Gaseous fuel activities | G19: 01-Jan-21 | H19: 31-Dec-21 | I19: LPG | J19: 228 | K19: kilograms | L19: Actual Data | M19: Frank Greene | N19: 18-Jul-23, 19:37 | P19: Calculated | Q19: 20-Jul-23, 00:40 | S19: South Africa electricity and natural gas accounting (1).xlsx
C20: 283987 | D20: Top of Hierarchy > Asia Pacific > Vantage_Shanghai | E20: FY22 (Jan. 1, 2022 - Dec. 31, 2022) | F20: Electricity (non-renewable) | G20: 01-Jan-22 | H20: 31-Dec-22 | I20: Electricity (non-renewable) | J20: 29409 | K20: Kilowatt hours | L20: Actual Data | M20: Frank Greene | N20: 28-Apr-23, 19:46 | P20: Calculated | Q20: 20-Jul-23, 00:40 | S20: Bill of eletronic and water of office (1).pdf, Shanghai electricity accounting.xlsx
C21: 1590441 | D21: Top of Hierarchy > Asia Pacific > Vantage_Shanghai | E21: FY22 (Jan. 1, 2022 - Dec. 31, 2022) | F21: Natural gas | G21: 01-Jan-22 | H21: 31-Dec-22 | I21: Natural gas | J21: 3788.4519 | K21: Hundred Thousand BTUs | L21: Estimated | M21: Daniella Giardetti | N21: 25-Jul-23, 17:50 | P21: Calculated | Q21: 25-Jul-23, 17:50 | R21: Estimated from square footage (CBECS 2012)
C22: 1590449 | D22: Top of Hierarchy > Asia Pacific > Vantage_Shanghai | E22: FY22 (Jan. 1, 2022 - Dec. 31, 2022) | F22: Refrigerant gasses | G22: 44562 | H22: 31-Dec-22 | I22: R-134A | J22: 2.7555584 | K22: kilograms | L22: Estimated | M22: Daniella Giardetti | N22: 25-Jul-23, 17:50 | P22: Calculated | Q22: 25-Jul-23, 17:50 | R22: Estimated from square footage. Assumed R134a.
C23: 4962 | D23: Top of Hierarchy > Asia Pacific > Vantage_Shanghai | E23: FY21 (Jan. 1, 2021 - Dec. 31, 2021) | F23: Electricity (non-renewable) | G23: 01-Jan-21 | H23: 31-Dec-21 | I23: Electricity (non-renewable) | J23: 32374 | K23: Kilowatt hours | L23: Estimated | M23: Frank Greene | N23: 27-Feb-23, 16:27 | P23: Calculated | Q23: 03-Aug-23, 20:59 | S23: Y2021Vantage Shanghai (1).xlsx, Electronic and water bill Y2021 (1).PDF
C24: 4988 | D24: Top of Hierarchy > Asia Pacific > Vantage_Shanghai | E24: FY21 (Jan. 1, 2021 - Dec. 31, 2021) | F24: Natural gas | G24: 01-Jan-21 | H24: 31-Dec-21 | I24: Natural gas | J24: 2.3422269e+08 | K24: British Thermal Units | L24: Estimated | M24: Jordyn Dean | N24: 27-Feb-23, 16:27 | P24: Calculated | Q24: 20-Jul-23, 00:40
C25: 5021 | D25: Top of Hierarchy > Asia Pacific > Vantage_Shanghai | E25: FY21 (Jan. 1, 2021 - Dec. 31, 2021) | F25: Liquid fuel activities | G25: 01-Jan-21 | H25: 31-Dec-21 | I25: Diesel (100% mineral diesel) | J25: 0 | K25: litres | L25: Estimated | M25: Jordyn Dean | N25: 27-Feb-23, 16:27 | P25: Calculated | Q25: 20-Jul-23, 00:40
C26: 5047 | D26: Top of Hierarchy > Asia Pacific > Vantage_Shanghai | E26: FY21 (Jan. 1, 2021 - Dec. 31, 2021) | F26: Refrigerant gasses | G26: 01-Jan-21 | H26: 31-Dec-21 | I26: HFC-134a | J26: 2.7556 | K26: kilograms | L26: Estimated | M26: Jordyn Dean | N26: 27-Feb-23, 16:27 | P26: Calculated | Q26: 20-Jul-23, 00:40
C27: 293319 | D27: Top of Hierarchy > Asia Pacific > Vantage_Mumbai | E27: FY22 (Jan. 1, 2022 - Dec. 31, 2022) | F27: Electricity (non-renewable) | G27: 01-Jan-22 | H27: 31-Dec-22 | I27: Electricity (non-renewable) | J27: 1000 | K27: Kilowatt hours | L27: Estimated | M27: Frank Greene | N27: 08-May-23, 17:22 | P27: Calculated | Q27: 20-Jul-23, 00:40 | R27: shared facility; not sure actual value but have estimation
C28: 293321 | D28: Top of Hierarchy > Asia Pacific > Vantage_Mumbai | E28: FY22 (Jan. 1, 2022 - Dec. 31, 2022) | F28: Liquid fuel activities | G28: 01-Jan-22 | H28: 31-Dec-22 | I28: Diesel (average biofuel blend) | J28: 0 | K28: US liquid gallons | L28: Actual Data | M28: Frank Greene | N28: 08-May-23, 17:23 | P28: Calculated | Q28: 20-Jul-23, 00:40
C29: 293323 | D29: Top of Hierarchy > Asia Pacific > Vantage_Mumbai | E29: FY22 (Jan. 1, 2022 - Dec. 31, 2022) | F29: Gaseous fuel activities | G29: 01-Jan-22 | H29: 31-Dec-22 | I29: Propane | J29: 0 | K29: US liquid gallons | L29: Actual Data | M29: Frank Greene | N29: 08-May-23, 17:23 | P29: Calculated | Q29: 20-Jul-23, 00:40
C30: 4957 | D30: Top of Hierarchy > Asia Pacific > Vantage_Mumbai | E30: FY21 (Jan. 1, 2021 - Dec. 31, 2021) | F30: Electricity (non-renewable) | G30: 01-Jan-21 | H30: 31-Dec-21 | I30: Electricity (non-renewable) | J30: 2441.65 | K30: Kilowatt hours | L30: Estimated | M30: Jordyn Dean | N30: 27-Feb-23, 16:27 | P30: Calculated | Q30: 20-Jul-23, 00:40
C31: 4984 | D31: Top of Hierarchy > Asia Pacific > Vantage_Mumbai | E31: FY21 (Jan. 1, 2021 - Dec. 31, 2021) | F31: Natural gas | G31: 01-Jan-21 | H31: 31-Dec-21 | I31: Natural gas | J31: 0 | K31: British Thermal Units | L31: Estimated | M31: Jordyn Dean | N31: 27-Feb-23, 16:27 | P31: Calculated | Q31: 20-Jul-23, 00:40
C32: 5018 | D32: Top of Hierarchy > Asia Pacific > Vantage_Mumbai | E32: FY21 (Jan. 1, 2021 - Dec. 31, 2021) | F32: Liquid fuel activities | G32: 01-Jan-21 | H32: 31-Dec-21 | I32: Diesel (100% mineral diesel) | J32: 0 | K32: litres | L32: Estimated | M32: Jordyn Dean | N32: 27-Feb-23, 16:27 | P32: Calculated | Q32: 20-Jul-23, 00:40
C33: 5043 | D33: Top of Hierarchy > Asia Pacific > Vantage_Mumbai | E33: FY21 (Jan. 1, 2021 - Dec. 31, 2021) | F33: Refrigerant gasses | G33: 01-Jan-21 | H33: 31-Dec-21 | I33: HFC-134a | J33: 0.0646 | K33: kilograms | L33: Estimated | M33: Jordyn Dean | N33: 27-Feb-23, 16:27 | P33: Calculated | Q33: 20-Jul-23, 00:40
C34: 11229 | D34: Top of Hierarchy > Europe > Vantage_Paris | E34: FY22 (Jan. 1, 2022 - Dec. 31, 2022) | F34: Electricity (non-renewable) | G34: 01-Jan-22 | H34: 31-Dec-22 | I34: Electricity (non-renewable) | J34: 0 | K34: Kilowatt hours | L34: Actual Data | M34: Frank Greene | N34: 16-Mar-23, 21:16 | P34: Calculated | Q34: 20-Jul-23, 00:40 | R34: This site closed Dec 31 2021
C35: 232861 | D35: Top of Hierarchy > Europe > Vantage_Paris | E35: FY22 (Jan. 1, 2022 - Dec. 31, 2022) | F35: Natural gas | G35: 01-Jan-22 | H35: 31-Dec-22 | I35: Natural gas | J35: 0 | K35: joules | L35: Actual Data | M35: Frank Greene | N35: 18-Apr-23, 21:48 | P35: Calculated | Q35: 20-Jul-23, 00:40 | R35: This site closed Dec 31 2021
C36: 232859 | D36: Top of Hierarchy > Europe > Vantage_Paris | E36: FY22 (Jan. 1, 2022 - Dec. 31, 2022) | F36: Liquid fuel activities | G36: 01-Jan-22 | H36: 31-Dec-22 | I36: Aviation spirit | J36: 0 | K36: British Thermal Units | L36: Actual Data | M36: Frank Greene | N36: 18-Apr-23, 21:47 | P36: Calculated | Q36: 20-Jul-23, 00:40 | R36: This site closed Dec 31 2021
C37: 232863 | D37: Top of Hierarchy > Europe > Vantage_Paris | E37: FY22 (Jan. 1, 2022 - Dec. 31, 2022) | F37: Refrigerant gasses | G37: 01-Jan-22 | H37: 31-Dec-22 | I37: HFC-23 | J37: 0 | K37: Kilotonne | L37: Actual Data | M37: Frank Greene | N37: 18-Apr-23, 21:48 | P37: Calculated | Q37: 20-Jul-23, 00:40 | R37: This site closed Dec 31 2021
C38: 294648 | D38: Top of Hierarchy > Europe > Vantage_Paris | E38: FY22 (Jan. 1, 2022 - Dec. 31, 2022) | F38: Gaseous fuel activities | G38: 01-Jan-22 | H38: 31-Dec-22 | I38: LPG | J38: 0 | K38: cubic feet | L38: Actual Data | M38: Frank Greene | N38: 09-May-23, 19:25 | P38: Calculated | Q38: 20-Jul-23, 00:40
C39: 4958 | D39: Top of Hierarchy > Europe > Vantage_Paris | E39: FY21 (Jan. 1, 2021 - Dec. 31, 2021) | F39: Electricity (non-renewable) | G39: 01-Jan-21 | H39: 31-Dec-21 | I39: Electricity (non-renewable) | J39: 23387 | K39: Kilowatt hours | L39: Actual Data | M39: Dylan Stogsdill | N39: 27-Feb-23, 16:27 | P39: Calculated | Q39: 20-Jul-23, 00:40 | S39: Paris Electricity Accounting
C40: 255499 | D40: Top of Hierarchy > Europe > Vantage_Leuna | E40: FY22 (Jan. 1, 2022 - Dec. 31, 2022) | F40: Electricity (non-renewable) | G40: 01-Jan-22 | H40: 31-Dec-22 | I40: Electricity (non-renewable) | J40: 15237808 | K40: Kilowatt hours | L40: Actual Data | M40: Frank Greene | N40: 26-Apr-23, 17:34 | P40: Calculated | Q40: 20-Jul-23, 00:40 | S40: InfraLeuna_Strom_Dampf_2022.zip, Energieträger 2022.xls
...

Sheet emissions
A1: Record ID | B1: Reporting Unit | C1: Reporting Unit Type | D1: Reporting Period Name | E1: Reporting Period Start Date | F1: Reporting Period End Date | G1: Activity Group | H1: Record Start Date | I1: Record End Date | J1: Activity | K1: Quantity | L1: Unit | M1: Data Quality | N1: Note | O1: Calculation Created At | P1: Calculation Updated At | Q1: Reporting Period Year | R1: Model Name | S1: Model Alias | T1: Model type | U1: Custom Factor | V1: Emission Factor Name | W1: Scope | X1: Scope Category | Y1: Matched Region | Z1: Matched Sub-region | AA1: Matched Country Code | AB1: Matched Country Region | AC1: Market-based | AD1: Impact Type | AE1: kgCO2e | AF1: EF Impact Value | AG1: EF Impact Unit | AH1: Consumption Value Multiplier | AI1: Consumption Value in EF Unit | AJ1: Assessment Report | AK1: Author | AL1: Source | AM1: Published Year | AN1: Data Year | AO1: Location tCO2e | AP1: Market tCO2e | AQ1: Reporting unit name | AR1: Reporting unit type2
A2: 293319 | B2: Top of Hierarchy > Asia Pacific > Vantage_Mumbai | C2: Office | D2: FY22 | E2: 44562 | F2: 44926 | G2: Electricity (non-renewable) | H2: 44562 | I2: 44926 | J2: Electricity (non-renewable) | K2: 1000 | L2: Kilowatt hours | M2: Estimated | N2: shared facility; not sure actual value but have estimation | O2: 2023-05-08, 17:22 | P2: 2023-07-20, 00:40 | Q2: 2022 | R2: electricity | S2: Electricity | T2: model | U2: FALSE | V2: ELECTRICITY; INDIA | W2: Scope 2 | X2: N/A | Y2: Asia | Z2: Southern Asia | AA2: IN | AC2: 0 | AD2: CH4 | AE2: 0.3 | AF2: RESTRICTED | AG2: KWH | AH2: 1 | AI2: 1000 | AJ2: AR4 | AK2: IEA | AL2: IEA (2022) | AM2: 2022 | AN2: 2020 | AO2: =IF(AND(emissions[[#This Row],[Market-based]]=0,emissions[[#This Row],[Impact Type]]="CO2E"),emissions[[#This Row],[kgCO2e]],0)/1000 -> 0 | AP2: =IF(AND(emissions[[#This Row],[Market-based]]=1,OR(emissions[[#This Row],[Impact Type]]="CO2E",emissions[[#This Row],[Impact Type]]="CO2E MKT")),emissions[[#This Row],[kgCO2e]],0)/1000 -> 0 | AQ2: =_xlfn.TEXTAFTER(emissions[[#This Row],[Reporting Unit]]," > ",LEN(emissions[[#This Row],[Reporting Unit]])-LEN(SUBSTITUTE(emissions[[#This Row],[Reporting Unit]],">",""))) -> Vantage_Mumbai | AR2: =_xlfn.XLOOKUP(emissions[[#This Row],[Reporting unit name]],hierarchy!$A:$A,hierarchy!$C:$C) -> Office
A3: 293319 | B3: Top of Hierarchy > Asia Pacific > Vantage_Mumbai | C3: Office | D3: FY22 | E3: 44562 | F3: 44926 | G3: Electricity (non-renewable) | H3: 44562 | I3: 44926 | J3: Electricity (non-renewable) | K3: 1000 | L3: Kilowatt hours | M3: Estimated | N3: shared facility; not sure actual value but have estimation | O3: 2023-05-08, 17:22 | P3: 2023-07-20, 00:40 | Q3: 2022 | R3: electricity | S3: Electricity | T3: model | U3: FALSE | V3: ELECTRICITY; INDIA | W3: Scope 2 | X3: N/A | Y3: Asia | Z3: Southern Asia | AA3: IN | AC3: 0 | AD3: CO2 | AE3: 689.3 | AF3: RESTRICTED | AG3: KWH | AH3: 1 | AI3: 1000 | AJ3: AR4 | AK3: IEA | AL3: IEA (2022) | AM3: 2022 | AN3: 2020 | AO3: =IF(AND(emissions[[#This Row],[Market-based]]=0,emissions[[#This Row],[Impact Type]]="CO2E"),emissions[[#This Row],[kgCO2e]],0)/1000 -> 0 | AP3: =IF(AND(emissions[[#This Row],[Market-based]]=1,OR(emissions[[#This Row],[Impact Type]]="CO2E",emissions[[#This Row],[Impact Type]]="CO2E MKT")),emissions[[#This Row],[kgCO2e]],0)/1000 -> 0 | AQ3: =_xlfn.TEXTAFTER(emissions[[#This Row],[Reporting Unit]]," > ",LEN(emissions[[#This Row],[Reporting Unit]])-LEN(SUBSTITUTE(emissions[[#This Row],[Reporting Unit]],">",""))) -> Vantage_Mumbai | AR3: =_xlfn.XLOOKUP(emissions[[#This Row],[Reporting unit name]],hierarchy!$A:$A,hierarchy!$C:$C) -> Office
A4: 293319 | B4: Top of Hierarchy > Asia Pacific > Vantage_Mumbai | C4: Office | D4: FY22 | E4: 44562 | F4: 44926 | G4: Electricity (non-renewable) | H4: 44562 | I4: 44926 | J4: Electricity (non-renewable) | K4: 1000 | L4: Kilowatt hours | M4: Estimated | N4: shared facility; not sure actual value but have estimation | O4: 2023-05-08, 17:22 | P4: 2023-07-20, 00:40 | Q4: 2022 | R4: electricity | S4: Electricity | T4: model | U4: FALSE | V4: ELECTRICITY; INDIA | W4: Scope 2 | X4: N/A | Y4: Asia | Z4: Southern Asia | AA4: IN | AC4: 0 | AD4: CO2E | AE4: 692.9 | AF4: RESTRICTED | AG4: KWH | AH4: 1 | AI4: 1000 | AJ4: AR4 | AK4: IEA | AL4: IEA (2022) | AM4: 2022 | AN4: 2020 | AO4: =IF(AND(emissions[[#This Row],[Market-based]]=0,emissions[[#This Row],[Impact Type]]="CO2E"),emissions[[#This Row],[kgCO2e]],0)/1000 -> 0.6929 | AP4: =IF(AND(emissions[[#This Row],[Market-based]]=1,OR(emissions[[#This Row],[Impact Type]]="CO2E",emissions[[#This Row],[Impact Type]]="CO2E MKT")),emissions[[#This Row],[kgCO2e]],0)/1000 -> 0 | AQ4: =_xlfn.TEXTAFTER(emissions[[#This Row],[Reporting Unit]]," > ",LEN(emissions[[#This Row],[Reporting Unit]])-LEN(SUBSTITUTE(emissions[[#This Row],[Reporting Unit]],">",""))) -> Vantage_Mumbai | AR4: =_xlfn.XLOOKUP(emissions[[#This Row],[Reporting unit name]],hierarchy!$A:$A,hierarchy!$C:$C) -> Office
A5: 293319 | B5: Top of Hierarchy > Asia Pacific > Vantage_Mumbai | C5: Office | D5: FY22 | E5: 44562 | F5: 44926 | G5: Electricity (non-renewable) | H5: 44562 | I5: 44926 | J5: Electricity (non-renewable) | K5: 1000 | L5: Kilowatt hours | M5: Estimated | N5: shared facility; not sure actual value but have estimation | O5: 2023-05-08, 17:22 | P5: 2023-07-20, 00:40 | Q5: 2022 | R5: electricity | S5: Electricity | T5: model | U5: FALSE | V5: ELECTRICITY; INDIA | W5: Scope 2 | X5: N/A | Y5: Asia | Z5: Southern Asia | AA5: IN | AC5: 0 | AD5: N2O | AE5: 3.3 | AF5: RESTRICTED | AG5: KWH | AH5: 1 | AI5: 1000 | AJ5: AR4 | AK5: IEA | AL5: IEA (2022) | AM5: 2022 | AN5: 2020 | AO5: =IF(AND(emissions[[#This Row],[Market-based]]=0,emissions[[#This Row],[Impact Type]]="CO2E"),emissions[[#This Row],[kgCO2e]],0)/1000 -> 0 | AP5: =IF(AND(emissions[[#This Row],[Market-based]]=1,OR(emissions[[#This Row],[Impact Type]]="CO2E",emissions[[#This Row],[Impact Type]]="CO2E MKT")),emissions[[#This Row],[kgCO2e]],0)/1000 -> 0 | AQ5: =_xlfn.TEXTAFTER(emissions[[#This Row],[Reporting Unit]]," > ",LEN(emissions[[#This Row],[Reporting Unit]])-LEN(SUBSTITUTE(emissions[[#This Row],[Reporting Unit]],">",""))) -> Vantage_Mumbai | AR5: =_xlfn.XLOOKUP(emissions[[#This Row],[Reporting unit name]],hierarchy!$A:$A,hierarchy!$C:$C) -> Office
A6: 293319 | B6: Top of Hierarchy > Asia Pacific > Vantage_Mumbai | C6: Office | D6: FY22 | E6: 44562 | F6: 44926 | G6: Electricity (non-renewable) | H6: 44562 | I6: 44926 | J6: Electricity (non-renewable) | K6: 1000 | L6: Kilowatt hours | M6: Estimated | N6: shared facility; not sure actual value but have estimation | O6: 2023-05-08, 17:22 | P6: 2023-07-20, 00:40 | Q6: 2022 | R6: electricity | S6: Electricity | T6: model | U6: FALSE | V6: ELECTRICITY; INDIA | W6: Scope 2 | X6: N/A | Y6: Asia | Z6: Southern Asia | AA6: IN | AC6: 1 | AD6: CH4 | AE6: 0.3 | AF6: RESTRICTED | AG6: KWH | AH6: 1 | AI6: 1000 | AJ6: AR4 | AK6: IEA | AL6: IEA (2022) | AM6: 2022 | AN6: 2020 | AO6: =IF(AND(emissions[[#This Row],[Market-based]]=0,emissions[[#This Row],[Impact Type]]="CO2E"),emissions[[#This Row],[kgCO2e]],0)/1000 -> 0 | AP6: =IF(AND(emissions[[#This Row],[Market-based]]=1,OR(emissions[[#This Row],[Impact Type]]="CO2E",emissions[[#This Row],[Impact Type]]="CO2E MKT")),emissions[[#This Row],[kgCO2e]],0)/1000 -> 0 | AQ6: =_xlfn.TEXTAFTER(emissions[[#This Row],[Reporting Unit]]," > ",LEN(emissions[[#This Row],[Reporting Unit]])-LEN(SUBSTITUTE(emissions[[#This Row],[Reporting Unit]],">",""))) -> Vantage_Mumbai | AR6: =_xlfn.XLOOKUP(emissions[[#This Row],[Reporting unit name]],hierarchy!$A:$A,hierarchy!$C:$C) -> Office
A7: 293319 | B7: Top of Hierarchy > Asia Pacific > Vantage_Mumbai | C7: Office | D7: FY22 | E7: 44562 | F7: 44926 | G7: Electricity (non-renewable) | H7: 44562 | I7: 44926 | J7: Electricity (non-renewable) | K7: 1000 | L7: Kilowatt hours | M7: Estimated | N7: shared facility; not sure actual value but have estimation | O7: 2023-05-08, 17:22 | P7: 2023-07-20, 00:40 | Q7: 2022 | R7: electricity | S7: Electricity | T7: model | U7: FALSE | V7: ELECTRICITY; INDIA | W7: Scope 2 | X7: N/A | Y7: Asia | Z7: Southern Asia | AA7: IN | AC7: 1 | AD7: CO2 | AE7: 689.3 | AF7: RESTRICTED | AG7: KWH | AH7: 1 | AI7: 1000 | AJ7: AR4 | AK7: IEA | AL7: IEA (2022) | AM7: 2022 | AN7: 2020 | AO7: =IF(AND(emissions[[#This Row],[Market-based]]=0,emissions[[#This Row],[Impact Type]]="CO2E"),emissions[[#This Row],[kgCO2e]],0)/1000 -> 0 | AP7: =IF(AND(emissions[[#This Row],[Market-based]]=1,OR(emissions[[#This Row],[Impact Type]]="CO2E",emissions[[#This Row],[Impact Type]]="CO2E MKT")),emissions[[#This Row],[kgCO2e]],0)/1000 -> 0 | AQ7: =_xlfn.TEXTAFTER(emissions[[#This Row],[Reporting Unit]]," > ",LEN(emissions[[#This Row],[Reporting Unit]])-LEN(SUBSTITUTE(emissions[[#This Row],[Reporting Unit]],">",""))) -> Vantage_Mumbai | AR7: =_xlfn.XLOOKUP(emissions[[#This Row],[Reporting unit name]],hierarchy!$A:$A,hierarchy!$C:$C) -> Office
A8: 293319 | B8: Top of Hierarchy > Asia Pacific > Vantage_Mumbai | C8: Office | D8: FY22 | E8: 44562 | F8: 44926 | G8: Electricity (non-renewable) | H8: 44562 | I8: 44926 | J8: Electricity (non-renewable) | K8: 1000 | L8: Kilowatt hours | M8: Estimated | N8: shared facility; not sure actual value but have estimation | O8: 2023-05-08, 17:22 | P8: 2023-07-20, 00:40 | Q8: 2022 | R8: electricity | S8: Electricity | T8: model | U8: FALSE | V8: ELECTRICITY; INDIA | W8: Scope 2 | X8: N/A | Y8: Asia | Z8: Southern Asia | AA8: IN | AC8: 1 | AD8: CO2E | AE8: 692.9 | AF8: RESTRICTED | AG8: KWH | AH8: 1 | AI8: 1000 | AJ8: AR4 | AK8: IEA | AL8: IEA (2022) | AM8: 2022 | AN8: 2020 | AO8: =IF(AND(emissions[[#This Row],[Market-based]]=0,emissions[[#This Row],[Impact Type]]="CO2E"),emissions[[#This Row],[kgCO2e]],0)/1000 -> 0 | AP8: =IF(AND(emissions[[#This Row],[Market-based]]=1,OR(emissions[[#This Row],[Impact Type]]="CO2E",emissions[[#This Row],[Impact Type]]="CO2E MKT")),emissions[[#This Row],[kgCO2e]],0)/1000 -> 0.6929 | AQ8: =_xlfn.TEXTAFTER(emissions[[#This Row],[Reporting Unit]]," > ",LEN(emissions[[#This Row],[Reporting Unit]])-LEN(SUBSTITUTE(emissions[[#This Row],[Reporting Unit]],">",""))) -> Vantage_Mumbai | AR8: =_xlfn.XLOOKUP(emissions[[#This Row],[Reporting unit name]],hierarchy!$A:$A,hierarchy!$C:$C) -> Office
A9: 293319 | B9: Top of Hierarchy > Asia Pacific > Vantage_Mumbai | C9: Office | D9: FY22 | E9: 44562 | F9: 44926 | G9: Electricity (non-renewable) | H9: 44562 | I9: 44926 | J9: Electricity (non-renewable) | K9: 1000 | L9: Kilowatt hours | M9: Estimated | N9: shared facility; not sure actual value but have estimation | O9: 2023-05-08, 17:22 | P9: 2023-07-20, 00:40 | Q9: 2022 | R9: electricity | S9: Electricity | T9: model | U9: FALSE | V9: ELECTRICITY; INDIA | W9: Scope 2 | X9: N/A | Y9: Asia | Z9: Southern Asia | AA9: IN | AC9: 1 | AD9: N2O | AE9: 3.3 | AF9: RESTRICTED | AG9: KWH | AH9: 1 | AI9: 1000 | AJ9: AR4 | AK9: IEA | AL9: IEA (2022) | AM9: 2022 | AN9: 2020 | AO9: =IF(AND(emissions[[#This Row],[Market-based]]=0,emissions[[#This Row],[Impact Type]]="CO2E"),emissions[[#This Row],[kgCO2e]],0)/1000 -> 0 | AP9: =IF(AND(emissions[[#This Row],[Market-based]]=1,OR(emissions[[#This Row],[Impact Type]]="CO2E",emissions[[#This Row],[Impact Type]]="CO2E MKT")),emissions[[#This Row],[kgCO2e]],0)/1000 -> 0 | AQ9: =_xlfn.TEXTAFTER(emissions[[#This Row],[Reporting Unit]]," > ",LEN(emissions[[#This Row],[Reporting Unit]])-LEN(SUBSTITUTE(emissions[[#This Row],[Reporting Unit]],">",""))) -> Vantage_Mumbai | AR9: =_xlfn.XLOOKUP(emissions[[#This Row],[Reporting unit name]],hierarchy!$A:$A,hierarchy!$C:$C) -> Office
A10: 293319 | B10: Top of Hierarchy > Asia Pacific > Vantage_Mumbai | C10: Office | D10: FY22 | E10: 44562 | F10: 44926 | G10: Electricity (non-renewable) | H10: 44562 | I10: 44926 | J10: Electricity (non-renewable) | K10: 1000 | L10: Kilowatt hours | M10: Estimated | N10: shared facility; not sure actual value but have estimation | O10: 2023-05-08, 17:22 | P10: 2023-07-20, 00:40 | Q10: 2022 | R10: electricity__t+d__wtt | S10: Electricity T&D WTT | T10: t+d_wtt | U10: FALSE | V10: ELECTRICITY T&D WTT; INDIA | W10: Scope 3 | X10: 3: Fuel- and Energy-Related Activities | Y10: Asia | Z10: Southern Asia | AA10: IN | AC10: 0 | AD10: CO2E | AE10: 28.27896 | AF10: 0.02827896 | AG10: KWH | AH10: 1 | AI10: 1000 | AJ10: AR4 | AK10: Anthesis | AL10: Anthesis (2022) | AM10: 2022 | AN10: 2020 | AO10: =IF(AND(emissions[[#This Row],[Market-based]]=0,emissions[[#This Row],[Impact Type]]="CO2E"),emissions[[#This Row],[kgCO2e]],0)/1000 -> 0.02827896 | AP10: =IF(AND(emissions[[#This Row],[Market-based]]=1,OR(emissions[[#This Row],[Impact Type]]="CO2E",emissions[[#This Row],[Impact Type]]="CO2E MKT")),emissions[[#This Row],[kgCO2e]],0)/1000 -> 0 | AQ10: =_xlfn.TEXTAFTER(emissions[[#This Row],[Reporting Unit]]," > ",LEN(emissions[[#This Row],[Reporting Unit]])-LEN(SUBSTITUTE(emissions[[#This Row],[Reporting Unit]],">",""))) -> Vantage_Mumbai | AR10: =_xlfn.XLOOKUP(emissions[[#This Row],[Reporting unit name]],hierarchy!$A:$A,hierarchy!$C:$C) -> Office
A11: 293319 | B11: Top of Hierarchy > Asia Pacific > Vantage_Mumbai | C11: Office | D11: FY22 | E11: 44562 | F11: 44926 | G11: Electricity (non-renewable) | H11: 44562 | I11: 44926 | J11: Electricity (non-renewable) | K11: 1000 | L11: Kilowatt hours | M11: Estimated | N11: shared facility; not sure actual value but have estimation | O11: 2023-05-08, 17:22 | P11: 2023-07-20, 00:40 | Q11: 2022 | R11: electricity__t+d__wtt | S11: Electricity T&D WTT | T11: t+d_wtt | U11: FALSE | V11: ELECTRICITY T&D WTT; INDIA | W11: Scope 3 | X11: 3: Fuel- and Energy-Related Activities | Y11: Asia | Z11: Southern Asia | AA11: IN | AC11: 1 | AD11: CO2E | AE11: 28.27896 | AF11: 0.02827896 | AG11: KWH | AH11: 1 | AI11: 1000 | AJ11: AR4 | AK11: Anthesis | AL11: Anthesis (2022) | AM11: 2022 | AN11: 2020 | AO11: =IF(AND(emissions[[#This Row],[Market-based]]=0,emissions[[#This Row],[Impact Type]]="CO2E"),emissions[[#This Row],[kgCO2e]],0)/1000 -> 0 | AP11: =IF(AND(emissions[[#This Row],[Market-based]]=1,OR(emissions[[#This Row],[Impact Type]]="CO2E",emissions[[#This Row],[Impact Type]]="CO2E MKT")),emissions[[#This Row],[kgCO2e]],0)/1000 -> 0.02827896 | AQ11: =_xlfn.TEXTAFTER(emissions[[#This Row],[Reporting Unit]]," > ",LEN(emissions[[#This Row],[Reporting Unit]])-LEN(SUBSTITUTE(emissions[[#This Row],[Reporting Unit]],">",""))) -> Vantage_Mumbai | AR11: =_xlfn.XLOOKUP(emissions[[#This Row],[Reporting unit name]],hierarchy!$A:$A,hierarchy!$C:$C) -> Office
A12: 293319 | B12: Top of Hierarchy > Asia Pacific > Vantage_Mumbai | C12: Office | D12: FY22 | E12: 44562 | F12: 44926 | G12: Electricity (non-renewable) | H12: 44562 | I12: 44926 | J12: Electricity (non-renewable) | K12: 1000 | L12: Kilowatt hours | M12: Estimated | N12: shared facility; not sure actual value but have estimation | O12: 2023-05-08, 17:22 | P12: 2023-07-20, 00:40 | Q12: 2022 | R12: electricity__wtt | S12: Electricity WTT | T12: wtt | U12: FALSE | V12: ELECTRICITY WTT; INDIA | W12: Scope 3 | X12: 3: Fuel- and Energy-Related Activities | Y12: Asia | Z12: Southern Asia | AA12: IN | AC12: 0 | AD12: CO2E | AE12: 159.82457 | AF12: 0.15982457 | AG12: KWH | AH12: 1 | AI12: 1000 | AJ12: AR4 | AK12: Anthesis | AL12: Anthesis (2022) | AM12: 2022 | AN12: 2020 | AO12: =IF(AND(emissions[[#This Row],[Market-based]]=0,emissions[[#This Row],[Impact Type]]="CO2E"),emissions[[#This Row],[kgCO2e]],0)/1000 -> 0.15982457 | AP12: =IF(AND(emissions[[#This Row],[Market-based]]=1,OR(emissions[[#This Row],[Impact Type]]="CO2E",emissions[[#This Row],[Impact Type]]="CO2E MKT")),emissions[[#This Row],[kgCO2e]],0)/1000 -> 0 | AQ12: =_xlfn.TEXTAFTER(emissions[[#This Row],[Reporting Unit]]," > ",LEN(emissions[[#This Row],[Reporting Unit]])-LEN(SUBSTITUTE(emissions[[#This Row],[Reporting Unit]],">",""))) -> Vantage_Mumbai | AR12: =_xlfn.XLOOKUP(emissions[[#This Row],[Reporting unit name]],hierarchy!$A:$A,hierarchy!$C:$C) -> Office
A13: 293319 | B13: Top of Hierarchy > Asia Pacific > Vantage_Mumbai | C13: Office | D13: FY22 | E13: 44562 | F13: 44926 | G13: Electricity (non-renewable) | H13: 44562 | I13: 44926 | J13: Electricity (non-renewable) | K13: 1000 | L13: Kilowatt hours | M13: Estimated | N13: shared facility; not sure actual value but have estimation | O13: 2023-05-08, 17:22 | P13: 2023-07-20, 00:40 | Q13: 2022 | R13: electricity__wtt | S13: Electricity WTT | T13: wtt | U13: FALSE | V13: ELECTRICITY WTT; INDIA | W13: Scope 3 | X13: 3: Fuel- and Energy-Related Activities | Y13: Asia | Z13: Southern Asia | AA13: IN | AC13: 1 | AD13: CO2E | AE13: 159.82457 | AF13: 0.15982457 | AG13: KWH | AH13: 1 | AI13: 1000 | AJ13: AR4 | AK13: Anthesis | AL13: Anthesis (2022) | AM13: 2022 | AN13: 2020 | AO13: =IF(AND(emissions[[#This Row],[Market-based]]=0,emissions[[#This Row],[Impact Type]]="CO2E"),emissions[[#This Row],[kgCO2e]],0)/1000 -> 0 | AP13: =IF(AND(emissions[[#This Row],[Market-based]]=1,OR(emissions[[#This Row],[Impact Type]]="CO2E",emissions[[#This Row],[Impact Type]]="CO2E MKT")),emissions[[#This Row],[kgCO2e]],0)/1000 -> 0.15982457 | AQ13: =_xlfn.TEXTAFTER(emissions[[#This Row],[Reporting Unit]]," > ",LEN(emissions[[#This Row],[Reporting Unit]])-LEN(SUBSTITUTE(emissions[[#This Row],[Reporting Unit]],">",""))) -> Vantage_Mumbai | AR13: =_xlfn.XLOOKUP(emissions[[#This Row],[Reporting unit name]],hierarchy!$A:$A,hierarchy!$C:$C) -> Office
A14: 293319 | B14: Top of Hierarchy > Asia Pacific > Vantage_Mumbai | C14: Office | D14: FY22 | E14: 44562 | F14: 44926 | G14: Electricity (non-renewable) | H14: 44562 | I14: 44926 | J14: Electricity (non-renewable) | K14: 1000 | L14: Kilowatt hours | M14: Estimated | N14: shared facility; not sure actual value but have estimation | O14: 2023-05-08, 17:22 | P14: 2023-07-20, 00:40 | Q14: 2022 | R14: electricity__t+d | S14: Electricity T&D | T14: t+d | U14: FALSE | V14: ELECTRICITY; TRANSMISSION AND DISTRIBUTION; INDIA | W14: Scope 3 | X14: 3: Fuel- and Energy-Related Activities | Y14: Asia | Z14: Southern Asia | AA14: IN | AC14: 0 | AD14: CO2E | AE14: 122.6 | AF14: RESTRICTED | AG14: KWH | AH14: 1 | AI14: 1000 | AJ14: AR4 | AK14: IEA | AL14: IEA (2022) | AM14: 2022 | AN14: 2020 | AO14: =IF(AND(emissions[[#This Row],[Market-based]]=0,emissions[[#This Row],[Impact Type]]="CO2E"),emissions[[#This Row],[kgCO2e]],0)/1000 -> 0.1226 | AP14: =IF(AND(emissions[[#This Row],[Market-based]]=1,OR(emissions[[#This Row],[Impact Type]]="CO2E",emissions[[#This Row],[Impact Type]]="CO2E MKT")),emissions[[#This Row],[kgCO2e]],0)/1000 -> 0 | AQ14: =_xlfn.TEXTAFTER(emissions[[#This Row],[Reporting Unit]]," > ",LEN(emissions[[#This Row],[Reporting Unit]])-LEN(SUBSTITUTE(emissions[[#This Row],[Reporting Unit]],">",""))) -> Vantage_Mumbai | AR14: =_xlfn.XLOOKUP(emissions[[#This Row],[Reporting unit name]],hierarchy!$A:$A,hierarchy!$C:$C) -> Office
A15: 293319 | B15: Top of Hierarchy > Asia Pacific > Vantage_Mumbai | C15: Office | D15: FY22 | E15: 44562 | F15: 44926 | G15: Electricity (non-renewable) | H15: 44562 | I15: 44926 | J15: Electricity (non-renewable) | K15: 1000 | L15: Kilowatt hours | M15: Estimated | N15: shared facility; not sure actual value but have estimation | O15: 2023-05-08, 17:22 | P15: 2023-07-20, 00:40 | Q15: 2022 | R15: electricity__t+d | S15: Electricity T&D | T15: t+d | U15: FALSE | V15: ELECTRICITY; TRANSMISSION AND DISTRIBUTION; INDIA | W15: Scope 3 | X15: 3: Fuel- and Energy-Related Activities | Y15: Asia | Z15: Southern Asia | AA15: IN | AC15: 1 | AD15: CO2E | AE15: 122.6 | AF15: RESTRICTED | AG15: KWH | AH15: 1 | AI15: 1000 | AJ15: AR4 | AK15: IEA | AL15: IEA (2022) | AM15: 2022 | AN15: 2020 | AO15: =IF(AND(emissions[[#This Row],[Market-based]]=0,emissions[[#This Row],[Impact Type]]="CO2E"),emissions[[#This Row],[kgCO2e]],0)/1000 -> 0 | AP15: =IF(AND(emissions[[#This Row],[Market-based]]=1,OR(emissions[[#This Row],[Impact Type]]="CO2E",emissions[[#This Row],[Impact Type]]="CO2E MKT")),emissions[[#This Row],[kgCO2e]],0)/1000 -> 0.1226 | AQ15: =_xlfn.TEXTAFTER(emissions[[#This Row],[Reporting Unit]]," > ",LEN(emissions[[#This Row],[Reporting Unit]])-LEN(SUBSTITUTE(emissions[[#This Row],[Reporting Unit]],">",""))) -> Vantage_Mumbai | AR15: =_xlfn.XLOOKUP(emissions[[#This Row],[Reporting unit name]],hierarchy!$A:$A,hierarchy!$C:$C) -> Office
A16: 293321 | B16: Top of Hierarchy > Asia Pacific > Vantage_Mumbai | C16: Office | D16: FY22 | E16: 44562 | F16: 44926 | G16: Liquid fuel activities | H16: 44562 | I16: 44926 | J16: Diesel (average biofuel blend) | K16: 0 | L16: US liquid gallons | M16: Actual Data | O16: 2023-05-08, 17:23 | P16: 2023-07-20, 00:40 | Q16: 2022 | R16: diesel_avg_biofuel_blend | S16: Diesel (Average Biofuel Blend) | T16: model | U16: FALSE | V16: FUELS; LIQUID FUELS; DIESEL (AVERAGE BIOFUEL BLEND) | W16: Scope 1 | X16: N/A | AC16: 0 | AD16: CH4 | AE16: 0 | AF16: 0.00026 | AG16: LITRES | AH16: 3.78541 | AI16: 0 | AJ16: AR4 | AK16: Defra | AL16: Defra (2022) | AM16: 2022 | AN16: 2020 | AO16: =IF(AND(emissions[[#This Row],[Market-based]]=0,emissions[[#This Row],[Impact Type]]="CO2E"),emissions[[#This Row],[kgCO2e]],0)/1000 -> 0 | AP16: =IF(AND(emissions[[#This Row],[Market-based]]=1,OR(emissions[[#This Row],[Impact Type]]="CO2E",emissions[[#This Row],[Impact Type]]="CO2E MKT")),emissions[[#This Row],[kgCO2e]],0)/1000 -> 0 | AQ16: =_xlfn.TEXTAFTER(emissions[[#This Row],[Reporting Unit]]," > ",LEN(emissions[[#This Row],[Reporting Unit]])-LEN(SUBSTITUTE(emissions[[#This Row],[Reporting Unit]],">",""))) -> Vantage_Mumbai | AR16: =_xlfn.XLOOKUP(emissions[[#This Row],[Reporting unit name]],hierarchy!$A:$A,hierarchy!$C:$C) -> Office
A17: 293321 | B17: Top of Hierarchy > Asia Pacific > Vantage_Mumbai | C17: Office | D17: FY22 | E17: 44562 | F17: 44926 | G17: Liquid fuel activities | H17: 44562 | I17: 44926 | J17: Diesel (average biofuel blend) | K17: 0 | L17: US liquid gallons | M17: Actual Data | O17: 2023-05-08, 17:23 | P17: 2023-07-20, 00:40 | Q17: 2022 | R17: diesel_avg_biofuel_blend | S17: Diesel (Average Biofuel Blend) | T17: model | U17: FALSE | V17: FUELS; LIQUID FUELS; DIESEL (AVERAGE BIOFUEL BLEND) | W17: Scope 1 | X17: N/A | AC17: 0 | AD17: CO2 | AE17: 0 | AF17: 2.52058 | AG17: LITRES | AH17: 3.78541 | AI17: 0 | AJ17: AR4 | AK17: Defra | AL17: Defra (2022) | AM17: 2022 | AN17: 2020 | AO17: =IF(AND(emissions[[#This Row],[Market-based]]=0,emissions[[#This Row],[Impact Type]]="CO2E"),emissions[[#This Row],[kgCO2e]],0)/1000 -> 0 | AP17: =IF(AND(emissions[[#This Row],[Market-based]]=1,OR(emissions[[#This Row],[Impact Type]]="CO2E",emissions[[#This Row],[Impact Type]]="CO2E MKT")),emissions[[#This Row],[kgCO2e]],0)/1000 -> 0 | AQ17: =_xlfn.TEXTAFTER(emissions[[#This Row],[Reporting Unit]]," > ",LEN(emissions[[#This Row],[Reporting Unit]])-LEN(SUBSTITUTE(emissions[[#This Row],[Reporting Unit]],">",""))) -> Vantage_Mumbai | AR17: =_xlfn.XLOOKUP(emissions[[#This Row],[Reporting unit name]],hierarchy!$A:$A,hierarchy!$C:$C) -> Office
A18: 293321 | B18: Top of Hierarchy > Asia Pacific > Vantage_Mumbai | C18: Office | D18: FY22 | E18: 44562 | F18: 44926 | G18: Liquid fuel activities | H18: 44562 | I18: 44926 | J18: Diesel (average biofuel blend) | K18: 0 | L18: US liquid gallons | M18: Actual Data | O18: 2023-05-08, 17:23 | P18: 2023-07-20, 00:40 | Q18: 2022 | R18: diesel_avg_biofuel_blend | S18: Diesel (Average Biofuel Blend) | T18: model | U18: FALSE | V18: FUELS; LIQUID FUELS; DIESEL (AVERAGE BIOFUEL BLEND) | W18: Scope 1 | X18: N/A | AC18: 0 | AD18: CO2E | AE18: 0 | AF18: 2.55784 | AG18: LITRES | AH18: 3.78541 | AI18: 0 | AJ18: AR4 | AK18: Defra | AL18: Defra (2022) | AM18: 2022 | AN18: 2020 | AO18: =IF(AND(emissions[[#This Row],[Market-based]]=0,emissions[[#This Row],[Impact Type]]="CO2E"),emissions[[#This Row],[kgCO2e]],0)/1000 -> 0 | AP18: =IF(AND(emissions[[#This Row],[Market-based]]=1,OR(emissions[[#This Row],[Impact Type]]="CO2E",emissions[[#This Row],[Impact Type]]="CO2E MKT")),emissions[[#This Row],[kgCO2e]],0)/1000 -> 0 | AQ18: =_xlfn.TEXTAFTER(emissions[[#This Row],[Reporting Unit]]," > ",LEN(emissions[[#This Row],[Reporting Unit]])-LEN(SUBSTITUTE(emissions[[#This Row],[Reporting Unit]],">",""))) -> Vantage_Mumbai | AR18: =_xlfn.XLOOKUP(emissions[[#This Row],[Reporting unit name]],hierarchy!$A:$A,hierarchy!$C:$C) -> Office
A19: 293321 | B19: Top of Hierarchy > Asia Pacific > Vantage_Mumbai | C19: Office | D19: FY22 | E19: 44562 | F19: 44926 | G19: Liquid fuel activities | H19: 44562 | I19: 44926 | J19: Diesel (average biofuel blend) | K19: 0 | L19: US liquid gallons | M19: Actual Data | O19: 2023-05-08, 17:23 | P19: 2023-07-20, 00:40 | Q19: 2022 | R19: diesel_avg_biofuel_blend | S19: Diesel (Average Biofuel Blend) | T19: model | U19: FALSE | V19: FUELS; LIQUID FUELS; DIESEL (AVERAGE BIOFUEL BLEND) | W19: Scope 1 | X19: N/A | AC19: 0 | AD19: N2O | AE19: 0 | AF19: 0.037 | AG19: LITRES | AH19: 3.78541 | AI19: 0 | AJ19: AR4 | AK19: Defra | AL19: Defra (2022) | AM19: 2022 | AN19: 2020 | AO19: =IF(AND(emissions[[#This Row],[Market-based]]=0,emissions[[#This Row],[Impact Type]]="CO2E"),emissions[[#This Row],[kgCO2e]],0)/1000 -> 0 | AP19: =IF(AND(emissions[[#This Row],[Market-based]]=1,OR(emissions[[#This Row],[Impact Type]]="CO2E",emissions[[#This Row],[Impact Type]]="CO2E MKT")),emissions[[#This Row],[kgCO2e]],0)/1000 -> 0 | AQ19: =_xlfn.TEXTAFTER(emissions[[#This Row],[Reporting Unit]]," > ",LEN(emissions[[#This Row],[Reporting Unit]])-LEN(SUBSTITUTE(emissions[[#This Row],[Reporting Unit]],">",""))) -> Vantage_Mumbai | AR19: =_xlfn.XLOOKUP(emissions[[#This Row],[Reporting unit name]],hierarchy!$A:$A,hierarchy!$C:$C) -> Office
A20: 293321 | B20: Top of Hierarchy > Asia Pacific > Vantage_Mumbai | C20: Office | D20: FY22 | E20: 44562 | F20: 44926 | G20: Liquid fuel activities | H20: 44562 | I20: 44926 | J20: Diesel (average biofuel blend) | K20: 0 | L20: US liquid gallons | M20: Actual Data | O20: 2023-05-08, 17:23 | P20: 2023-07-20, 00:40 | Q20: 2022 | R20: diesel_avg_biofuel_blend | S20: Diesel (Average Biofuel Blend) | T20: model | U20: FALSE | V20: FUELS; LIQUID FUELS; DIESEL (AVERAGE BIOFUEL BLEND) | W20: Scope 1 | X20: N/A | AC20: 1 | AD20: CH4 | AE20: 0 | AF20: 0.00026 | AG20: LITRES | AH20: 3.78541 | AI20: 0 | AJ20: AR4 | AK20: Defra | AL20: Defra (2022) | AM20: 2022 | AN20: 2020 | AO20: =IF(AND(emissions[[#This Row],[Market-based]]=0,emissions[[#This Row],[Impact Type]]="CO2E"),emissions[[#This Row],[kgCO2e]],0)/1000 -> 0 | AP20: =IF(AND(emissions[[#This Row],[Market-based]]=1,OR(emissions[[#This Row],[Impact Type]]="CO2E",emissions[[#This Row],[Impact Type]]="CO2E MKT")),emissions[[#This Row],[kgCO2e]],0)/1000 -> 0 | AQ20: =_xlfn.TEXTAFTER(emissions[[#This Row],[Reporting Unit]]," > ",LEN(emissions[[#This Row],[Reporting Unit]])-LEN(SUBSTITUTE(emissions[[#This Row],[Reporting Unit]],">",""))) -> Vantage_Mumbai | AR20: =_xlfn.XLOOKUP(emissions[[#This Row],[Reporting unit name]],hierarchy!$A:$A,hierarchy!$C:$C) -> Office
A21: 293321 | B21: Top of Hierarchy > Asia Pacific > Vantage_Mumbai | C21: Office | D21: FY22 | E21: 44562 | F21: 44926 | G21: Liquid fuel activities | H21: 44562 | I21: 44926 | J21: Diesel (average biofuel blend) | K21: 0 | L21: US liquid gallons | M21: Actual Data | O21: 2023-05-08, 17:23 | P21: 2023-07-20, 00:40 | Q21: 2022 | R21: diesel_avg_biofuel_blend | S21: Diesel (Average Biofuel Blend) | T21: model | U21: FALSE | V21: FUELS; LIQUID FUELS; DIESEL (AVERAGE BIOFUEL BLEND) | W21: Scope 1 | X21: N/A | AC21: 1 | AD21: CO2 | AE21: 0 | AF21: 2.52058 | AG21: LITRES | AH21: 3.78541 | AI21: 0 | AJ21: AR4 | AK21: Defra | AL21: Defra (2022) | AM21: 2022 | AN21: 2020 | AO21: =IF(AND(emissions[[#This Row],[Market-based]]=0,emissions[[#This Row],[Impact Type]]="CO2E"),emissions[[#This Row],[kgCO2e]],0)/1000 -> 0 | AP21: =IF(AND(emissions[[#This Row],[Market-based]]=1,OR(emissions[[#This Row],[Impact Type]]="CO2E",emissions[[#This Row],[Impact Type]]="CO2E MKT")),emissions[[#This Row],[kgCO2e]],0)/1000 -> 0 | AQ21: =_xlfn.TEXTAFTER(emissions[[#This Row],[Reporting Unit]]," > ",LEN(emissions[[#This Row],[Reporting Unit]])-LEN(SUBSTITUTE(emissions[[#This Row],[Reporting Unit]],">",""))) -> Vantage_Mumbai | AR21: =_xlfn.XLOOKUP(emissions[[#This Row],[Reporting unit name]],hierarchy!$A:$A,hierarchy!$C:$C) -> Office
A22: 293321 | B22: Top of Hierarchy > Asia Pacific > Vantage_Mumbai | C22: Office | D22: FY22 | E22: 44562 | F22: 44926 | G22: Liquid fuel activities | H22: 44562 | I22: 44926 | J22: Diesel (average biofuel blend) | K22: 0 | L22: US liquid gallons | M22: Actual Data | O22: 2023-05-08, 17:23 | P22: 2023-07-20, 00:40 | Q22: 2022 | R22: diesel_avg_biofuel_blend | S22: Diesel (Average Biofuel Blend) | T22: model | U22: FALSE | V22: FUELS; LIQUID FUELS; DIESEL (AVERAGE BIOFUEL BLEND) | W22: Scope 1 | X22: N/A | AC22: 1 | AD22: CO2E | AE22: 0 | AF22: 2.55784 | AG22: LITRES | AH22: 3.78541 | AI22: 0 | AJ22: AR4 | AK22: Defra | AL22: Defra (2022) | AM22: 2022 | AN22: 2020 | AO22: =IF(AND(emissions[[#This Row],[Market-based]]=0,emissions[[#This Row],[Impact Type]]="CO2E"),emissions[[#This Row],[kgCO2e]],0)/1000 -> 0 | AP22: =IF(AND(emissions[[#This Row],[Market-based]]=1,OR(emissions[[#This Row],[Impact Type]]="CO2E",emissions[[#This Row],[Impact Type]]="CO2E MKT")),emissions[[#This Row],[kgCO2e]],0)/1000 -> 0 | AQ22: =_xlfn.TEXTAFTER(emissions[[#This Row],[Reporting Unit]]," > ",LEN(emissions[[#This Row],[Reporting Unit]])-LEN(SUBSTITUTE(emissions[[#This Row],[Reporting Unit]],">",""))) -> Vantage_Mumbai | AR22: =_xlfn.XLOOKUP(emissions[[#This Row],[Reporting unit name]],hierarchy!$A:$A,hierarchy!$C:$C) -> Office
A23: 293321 | B23: Top of Hierarchy > Asia Pacific > Vantage_Mumbai | C23: Office | D23: FY22 | E23: 44562 | F23: 44926 | G23: Liquid fuel activities | H23: 44562 | I23: 44926 | J23: Diesel (average biofuel blend) | K23: 0 | L23: US liquid gallons | M23: Actual Data | O23: 2023-05-08, 17:23 | P23: 2023-07-20, 00:40 | Q23: 2022 | R23: diesel_avg_biofuel_blend | S23: Diesel (Average Biofuel Blend) | T23: model | U23: FALSE | V23: FUELS; LIQUID FUELS; DIESEL (AVERAGE BIOFUEL BLEND) | W23: Scope 1 | X23: N/A | AC23: 1 | AD23: N2O | AE23: 0 | AF23: 0.037 | AG23: LITRES | AH23: 3.78541 | AI23: 0 | AJ23: AR4 | AK23: Defra | AL23: Defra (2022) | AM23: 2022 | AN23: 2020 | AO23: =IF(AND(emissions[[#This Row],[Market-based]]=0,emissions[[#This Row],[Impact Type]]="CO2E"),emissions[[#This Row],[kgCO2e]],0)/1000 -> 0 | AP23: =IF(AND(emissions[[#This Row],[Market-based]]=1,OR(emissions[[#This Row],[Impact Type]]="CO2E",emissions[[#This Row],[Impact Type]]="CO2E MKT")),emissions[[#This Row],[kgCO2e]],0)/1000 -> 0 | AQ23: =_xlfn.TEXTAFTER(emissions[[#This Row],[Reporting Unit]]," > ",LEN(emissions[[#This Row],[Reporting Unit]])-LEN(SUBSTITUTE(emissions[[#This Row],[Reporting Unit]],">",""))) -> Vantage_Mumbai | AR23: =_xlfn.XLOOKUP(emissions[[#This Row],[Reporting unit name]],hierarchy!$A:$A,hierarchy!$C:$C) -> Office
A24: 293321 | B24: Top of Hierarchy > Asia Pacific > Vantage_Mumbai | C24: Office | D24: FY22 | E24: 44562 | F24: 44926 | G24: Liquid fuel activities | H24: 44562 | I24: 44926 | J24: Diesel (average biofuel blend) | K24: 0 | L24: US liquid gallons | M24: Actual Data | O24: 2023-05-08, 17:23 | P24: 2023-07-20, 00:40 | Q24: 2022 | R24: diesel_avg_biofuel_blend__wtt | S24: Diesel (Average Biofuel Blend) WTT | T24: wtt | U24: FALSE | V24: WTT- FUELS; LIQUID FUELS; DIESEL (AVERAGE BIOFUEL BLEND) | W24: Scope 3 | X24: 3: Fuel- and Energy-Related Activities | AC24: 0 | AD24: CO2E | AE24: 0 | AF24: 0.60986 | AG24: LITRES | AH24: 3.78541 | AI24: 0 | AJ24: AR4 | AK24: Defra | AL24: Defra (2022) | AM24: 2022 | AN24: 2020 | AO24: =IF(AND(emissions[[#This Row],[Market-based]]=0,emissions[[#This Row],[Impact Type]]="CO2E"),emissions[[#This Row],[kgCO2e]],0)/1000 -> 0 | AP24: =IF(AND(emissions[[#This Row],[Market-based]]=1,OR(emissions[[#This Row],[Impact Type]]="CO2E",emissions[[#This Row],[Impact Type]]="CO2E MKT")),emissions[[#This Row],[kgCO2e]],0)/1000 -> 0 | AQ24: =_xlfn.TEXTAFTER(emissions[[#This Row],[Reporting Unit]]," > ",LEN(emissions[[#This Row],[Reporting Unit]])-LEN(SUBSTITUTE(emissions[[#This Row],[Reporting Unit]],">",""))) -> Vantage_Mumbai | AR24: =_xlfn.XLOOKUP(emissions[[#This Row],[Reporting unit name]],hierarchy!$A:$A,hierarchy!$C:$C) -> Office
A25: 293321 | B25: Top of Hierarchy > Asia Pacific > Vantage_Mumbai | C25: Office | D25: FY22 | E25: 44562 | F25: 44926 | G25: Liquid fuel activities | H25: 44562 | I25: 44926 | J25: Diesel (average biofuel blend) | K25: 0 | L25: US liquid gallons | M25: Actual Data | O25: 2023-05-08, 17:23 | P25: 2023-07-20, 00:40 | Q25: 2022 | R25: diesel_avg_biofuel_blend__wtt | S25: Diesel (Average Biofuel Blend) WTT | T25: wtt | U25: FALSE | V25: WTT- FUELS; LIQUID FUELS; DIESEL (AVERAGE BIOFUEL BLEND) | W25: Scope 3 | X25: 3: Fuel- and Energy-Related Activities | AC25: 1 | AD25: CO2E | AE25: 0 | AF25: 0.60986 | AG25: LITRES | AH25: 3.78541 | AI25: 0 | AJ25: AR4 | AK25: Defra | AL25: Defra (2022) | AM25: 2022 | AN25: 2020 | AO25: =IF(AND(emissions[[#This Row],[Market-based]]=0,emissions[[#This Row],[Impact Type]]="CO2E"),emissions[[#This Row],[kgCO2e]],0)/1000 -> 0 | AP25: =IF(AND(emissions[[#This Row],[Market-based]]=1,OR(emissions[[#This Row],[Impact Type]]="CO2E",emissions[[#This Row],[Impact Type]]="CO2E MKT")),emissions[[#This Row],[kgCO2e]],0)/1000 -> 0 | AQ25: =_xlfn.TEXTAFTER(emissions[[#This Row],[Reporting Unit]]," > ",LEN(emissions[[#This Row],[Reporting Unit]])-LEN(SUBSTITUTE(emissions[[#This Row],[Reporting Unit]],">",""))) -> Vantage_Mumbai | AR25: =_xlfn.XLOOKUP(emissions[[#This Row],[Reporting unit name]],hierarchy!$A:$A,hierarchy!$C:$C) -> Office
A26: 293323 | B26: Top of Hierarchy > Asia Pacific > Vantage_Mumbai | C26: Office | D26: FY22 | E26: 44562 | F26: 44926 | G26: Gaseous fuel activities | H26: 44562 | I26: 44926 | J26: Propane | K26: 0 | L26: US liquid gallons | M26: Actual Data | O26: 2023-05-08, 17:23 | P26: 2023-07-20, 00:40 | Q26: 2022 | R26: propane | S26: Propane | T26: model | U26: FALSE | V26: FUELS; GASEOUS FUELS; PROPANE | W26: Scope 1 | X26: N/A | AC26: 0 | AD26: CH4 | AE26: 0 | AF26: 0.00119 | AG26: LITRES | AH26: 3.78541 | AI26: 0 | AJ26: AR4 | AK26: Defra | AL26: Defra (2022) | AM26: 2022 | AN26: 2020 | AO26: =IF(AND(emissions[[#This Row],[Market-based]]=0,emissions[[#This Row],[Impact Type]]="CO2E"),emissions[[#This Row],[kgCO2e]],0)/1000 -> 0 | AP26: =IF(AND(emissions[[#This Row],[Market-based]]=1,OR(emissions[[#This Row],[Impact Type]]="CO2E",emissions[[#This Row],[Impact Type]]="CO2E MKT")),emissions[[#This Row],[kgCO2e]],0)/1000 -> 0 | AQ26: =_xlfn.TEXTAFTER(emissions[[#This Row],[Reporting Unit]]," > ",LEN(emissions[[#This Row],[Reporting Unit]])-LEN(SUBSTITUTE(emissions[[#This Row],[Reporting Unit]],">",""))) -> Vantage_Mumbai | AR26: =_xlfn.XLOOKUP(emissions[[#This Row],[Reporting unit name]],hierarchy!$A:$A,hierarchy!$C:$C) -> Office
A27: 293323 | B27: Top of Hierarchy > Asia Pacific > Vantage_Mumbai | C27: Office | D27: FY22 | E27: 44562 | F27: 44926 | G27: Gaseous fuel activities | H27: 44562 | I27: 44926 | J27: Propane | K27: 0 | L27: US liquid gallons | M27: Actual Data | O27: 2023-05-08, 17:23 | P27: 2023-07-20, 00:40 | Q27: 2022 | R27: propane | S27: Propane | T27: model | U27: FALSE | V27: FUELS; GASEOUS FUELS; PROPANE | W27: Scope 1 | X27: N/A | AC27: 0 | AD27: CO2 | AE27: 0 | AF27: 1.5414 | AG27: LITRES | AH27: 3.78541 | AI27: 0 | AJ27: AR4 | AK27: Defra | AL27: Defra (2022) | AM27: 2022 | AN27: 2020 | AO27: =IF(AND(emissions[[#This Row],[Market-based]]=0,emissions[[#This Row],[Impact Type]]="CO2E"),emissions[[#This Row],[kgCO2e]],0)/1000 -> 0 | AP27: =IF(AND(emissions[[#This Row],[Market-based]]=1,OR(emissions[[#This Row],[Impact Type]]="CO2E",emissions[[#This Row],[Impact Type]]="CO2E MKT")),emissions[[#This Row],[kgCO2e]],0)/1000 -> 0 | AQ27: =_xlfn.TEXTAFTER(emissions[[#This Row],[Reporting Unit]]," > ",LEN(emissions[[#This Row],[Reporting Unit]])-LEN(SUBSTITUTE(emissions[[#This Row],[Reporting Unit]],">",""))) -> Vantage_Mumbai | AR27: =_xlfn.XLOOKUP(emissions[[#This Row],[Reporting unit name]],hierarchy!$A:$A,hierarchy!$C:$C) -> Office
... A35: 293323 | B35: Top of Hierarchy > Asia Pacific > Vantage_Mumbai | C35: Office | D35: FY22 | E35: 44562 | F35: 44926 | G35: Gaseous fuel activities | H35: 44562 | I35: 44926 | J35: Propane | K35: 0 | L35: US liquid gallons | M35: Actual Data | O35: 2023-05-08, 17:23 | P35: 2023-07-20, 00:40 | Q35: 2022 | R35: propane__wtt | S35: Propane WTT | T35: wtt | U35: FALSE | V35: WTT- FUELS; GASEOUS FUELS; PROPANE | W35: Scope 3 | X35: 3: Fuel- and Energy-Related Activities | AC35: 1 | AD35: CO2E | AE35: 0 | AF35: 0.18046 | AG35: LITRES | AH35: 3.78541 | AI35: 0 | AJ35: AR4 | AK35: Defra | AL35: Defra (2022) | AM35: 2022 | AN35: 2020 | AO35: =IF(AND(emissions[[#This Row],[Market-based]]=0,emissions[[#This Row],[Impact Type]]="CO2E"),emissions[[#This Row],[kgCO2e]],0)/1000 -> 0 | AP35: =IF(AND(emissions[[#This Row],[Market-based]]=1,OR(emissions[[#This Row],[Impact Type]]="CO2E",emissions[[#This Row],[Impact Type]]="CO2E MKT")),emissions[[#This Row],[kgCO2e]],0)/1000 -> 0 | AQ35: =_xlfn.TEXTAFTER(emissions[[#This Row],[Reporting Unit]]," > ",LEN(emissions[[#This Row],[Reporting Unit]])-LEN(SUBSTITUTE(emissions[[#This Row],[Reporting Unit]],">",""))) -> Vantage_Mumbai | AR35: =_xlfn.XLOOKUP(emissions[[#This Row],[Reporting unit name]],hierarchy!$A:$A,hierarchy!$C:$C) -> Office
