Workbook

Sheet Overview
B7: Energy & Emissions Summary
S8: =88584-106088 -> -17504
B9: 2023 Emissions by Scope | S9: =S8/106088 -> -0.1649951
B11: Scope | C11: Market-based (mtons CO2e) | D11: Location-based (mtons CO2e)
B12: Scope 1 | C12: =GETPIVOTDATA("Sum of Total CO2e Emissions (Market Based) (mtons CO2-e)",Pivot!$B$6,"Scope","Scope 1") -> 57269.823 | D12: =GETPIVOTDATA("Sum of Total CO2e Emissions (Location-Based) (mtons CO2-e)",Pivot!$B$6,"Scope","Scope 1") -> 57269.823
B13: Scope 2 | C13: =GETPIVOTDATA("Sum of Total CO2e Emissions (Market Based) (mtons CO2-e)",Pivot!$B$6,"Scope","Scope 2") -> 31315.117 | D13: =GETPIVOTDATA("Sum of Total CO2e Emissions (Location-Based) (mtons CO2-e)",Pivot!$B$6,"Scope","Scope 2") -> 35782.582
B14: Scope 3 | C14: =GETPIVOTDATA("Sum of Total CO2e Emissions (Market Based) (mtons CO2-e)",Pivot!$B$6,"Scope","Scope 3") -> 1492.37 | D14: =GETPIVOTDATA("Sum of Total CO2e Emissions (Location-Based) (mtons CO2-e)",Pivot!$B$6,"Scope","Scope 3") -> 1492.37
B15: Total | C15: =SUM(C12:C14) -> 90077.31 | D15: =SUM(D12:D14) -> 94544.775
B17: 2023 Emissions by Source
B19: Scope | C19: Source | D19: Market-based (mtons CO2e) | E19: Location-based (mtons CO2e)
B20: Scope 1 | C20: Diesel | D20: =_xlfn.XLOOKUP($C20,Pivot!$C$8:$C$29,Pivot!D$8:D$29) -> 246.212 | E20: =_xlfn.XLOOKUP($C20,Pivot!$C$8:$C$29,Pivot!E$8:E$29) -> 246.212
C21: Diesel - Clear Diesel | D21: =_xlfn.XLOOKUP($C21,Pivot!$C$8:$C$29,Pivot!D$8:D$29) -> 34.132 | E21: =_xlfn.XLOOKUP($C21,Pivot!$C$8:$C$29,Pivot!E$8:E$29) -> 34.132
C22: Dry Ice | D22: =_xlfn.XLOOKUP($C22,Pivot!$C$8:$C$29,Pivot!D$8:D$29) -> 42.156 | E22: =_xlfn.XLOOKUP($C22,Pivot!$C$8:$C$29,Pivot!E$8:E$29) -> 42.156
C23: Gas Oil | D23: =_xlfn.XLOOKUP($C23,Pivot!$C$8:$C$29,Pivot!D$8:D$29) -> 1.946 | E23: =_xlfn.XLOOKUP($C23,Pivot!$C$8:$C$29,Pivot!E$8:E$29) -> 1.946
C24: Gasoline | D24: =_xlfn.XLOOKUP($C24,Pivot!$C$8:$C$29,Pivot!D$8:D$29) -> 20.708 | E24: =_xlfn.XLOOKUP($C24,Pivot!$C$8:$C$29,Pivot!E$8:E$29) -> 20.708
C25: Gasoline - 87 octane (regular) | D25: =_xlfn.XLOOKUP($C25,Pivot!$C$8:$C$29,Pivot!D$8:D$29) -> 112.847 | E25: =_xlfn.XLOOKUP($C25,Pivot!$C$8:$C$29,Pivot!E$8:E$29) -> 112.847
C26: Gasoline - 95 octane (premium) | D26: =_xlfn.XLOOKUP($C26,Pivot!$C$8:$C$29,Pivot!D$8:D$29) -> 114.702 | E26: =_xlfn.XLOOKUP($C26,Pivot!$C$8:$C$29,Pivot!E$8:E$29) -> 114.702
C27: Liquefied Petroleum Gas (LPG) | D27: =_xlfn.XLOOKUP($C27,Pivot!$C$8:$C$29,Pivot!D$8:D$29) -> 3.428 | E27: =_xlfn.XLOOKUP($C27,Pivot!$C$8:$C$29,Pivot!E$8:E$29) -> 3.428
C28: Natural Gas | D28: =_xlfn.XLOOKUP($C28,Pivot!$C$8:$C$29,Pivot!D$8:D$29) -> 56515.751 | E28: =_xlfn.XLOOKUP($C28,Pivot!$C$8:$C$29,Pivot!E$8:E$29) -> 56515.751
C29: Propane | D29: =_xlfn.XLOOKUP($C29,Pivot!$C$8:$C$29,Pivot!D$8:D$29) -> 11.957 | E29: =_xlfn.XLOOKUP($C29,Pivot!$C$8:$C$29,Pivot!E$8:E$29) -> 11.957
C30: Fertilizer | D30: =_xlfn.XLOOKUP($C30,Pivot!$C$8:$C$29,Pivot!D$8:D$29) -> 2.352 | E30: =_xlfn.XLOOKUP($C30,Pivot!$C$8:$C$29,Pivot!E$8:E$29) -> 2.352
C31: Refrigerant | D31: =_xlfn.XLOOKUP($C31,Pivot!$C$8:$C$29,Pivot!D$8:D$29) -> 163.632 | E31: =_xlfn.XLOOKUP($C31,Pivot!$C$8:$C$29,Pivot!E$8:E$29) -> 163.632
B32: Scope 2 | C32: Electric Power | D32: =_xlfn.XLOOKUP($C32,Pivot!$C$8:$C$29,Pivot!D$8:D$29) -> 26570.229 | E32: =_xlfn.XLOOKUP($C32,Pivot!$C$8:$C$29,Pivot!E$8:E$29) -> 31037.694
C33: Steam | D33: =_xlfn.XLOOKUP(C33,Pivot!$C$8:$C$29,Pivot!$D$8:$D$29) -> 4744.888 | E33: =_xlfn.XLOOKUP($C33,Pivot!$C$8:$C$29,Pivot!E$8:E$29) -> 4744.888
B34: Scope 3 | C34: Hazardous Waste | D34: =_xlfn.XLOOKUP(C34,Pivot!$C$8:$C$29,Pivot!$D$8:$D$29) -> 115.996 | E34: =_xlfn.XLOOKUP($C34,Pivot!$C$8:$C$29,Pivot!E$8:E$29) -> 115.996
C35: Hazardous Waste - Recycled | D35: =_xlfn.XLOOKUP(C35,Pivot!$C$8:$C$29,Pivot!$D$8:$D$29) -> 0.024 | E35: =_xlfn.XLOOKUP($C35,Pivot!$C$8:$C$29,Pivot!E$8:E$29) -> 0.024
C36: Non-Hazardous Waste | D36: =_xlfn.XLOOKUP(C36,Pivot!$C$8:$C$29,Pivot!$D$8:$D$29) -> 995.21 | E36: =_xlfn.XLOOKUP($C36,Pivot!$C$8:$C$29,Pivot!E$8:E$29) -> 995.21
C37: Non-Hazardous Waste - Recycling | D37: =_xlfn.XLOOKUP(C37,Pivot!$C$8:$C$29,Pivot!$D$8:$D$29) -> 2.024 | E37: =_xlfn.XLOOKUP($C37,Pivot!$C$8:$C$29,Pivot!E$8:E$29) -> 2.024
C38: Solid Waste | D38: =_xlfn.XLOOKUP(C38,Pivot!$C$8:$C$29,Pivot!$D$8:$D$29) -> 0 | E38: =_xlfn.XLOOKUP($C38,Pivot!$C$8:$C$29,Pivot!E$8:E$29) -> 0
C39: Waste | D39: =_xlfn.XLOOKUP(C39,Pivot!$C$8:$C$29,Pivot!$D$8:$D$29) -> 379.116 | E39: =_xlfn.XLOOKUP($C39,Pivot!$C$8:$C$29,Pivot!E$8:E$29) -> 379.116
B40: Total | D40: =SUM(D20:D39) -> 90077.31 | E40: =SUM(E20:E39) -> 94544.775
B42: 2023 Volume by Source
B44: Scope | C44: Source | D44: UOM | E44: Volume
B45: Scope 1 | C45: Diesel | D45: MWh | E45: =_xlfn.XLOOKUP(C45,Pivot!$C$39:$C$60,Pivot!$E$39:$E$60) -> 1052.0066
B46: Scope 1 | C46: Diesel - Clear Diesel | D46: gallons | E46: =_xlfn.XLOOKUP(C46,Pivot!$C$39:$C$60,Pivot!$E$39:$E$60) -> 3588
B47: Scope 1 | C47: Dry Ice | D47: metric tons | E47: =_xlfn.XLOOKUP(C47,Pivot!$C$39:$C$60,Pivot!$E$39:$E$60) -> 42.15687
B48: Scope 1 | C48: Fertilizer | D48: mtons CO2-e | E48: =_xlfn.XLOOKUP(C48,Pivot!$C$39:$C$60,Pivot!$E$39:$E$60) -> 2.352
B49: Scope 1 | C49: Gas Oil | D49: MWh | E49: =_xlfn.XLOOKUP(C49,Pivot!$C$39:$C$60,Pivot!$E$39:$E$60) -> 7.6787
B50: Scope 1 | C50: Gasoline | D50: MWh | E50: =_xlfn.XLOOKUP(C50,Pivot!$C$39:$C$60,Pivot!$E$39:$E$60) -> 95.526332
B51: Scope 1 | C51: Gasoline - 87 octane (regular) | D51: MWh | E51: =_xlfn.XLOOKUP(C51,Pivot!$C$39:$C$60,Pivot!$E$39:$E$60) -> 520.50072
...

Sheet Pivot
B4: Year | C4: 2023 | K4: Water
C5: Emissions by Source | K5: Sum of Total Water Usage (gallons)
D6: Values | K6: Year | L6: Total
B7: Scope | C7: Source | D7: Sum of Total CO2e Emissions (Market Based) (mtons CO2-e) | E7: Sum of Total CO2e Emissions (Location-Based) (mtons CO2-e) | K7: 2023 | L7: 3.8131162e+09
B8: Scope 1 | C8: Diesel | D8: 246.212 | E8: 246.212 | K8: Grand Total | L8: 3.8131162e+09
C9: Diesel - Clear Diesel | D9: 34.132 | E9: 34.132
C10: Dry Ice | D10: 42.156 | E10: 42.156
C11: Gas Oil | D11: 1.946 | E11: 1.946
C12: Gasoline | D12: 20.708 | E12: 20.708
C13: Gasoline - 87 octane (regular) | D13: 112.847 | E13: 112.847
C14: Gasoline - 95 octane (premium) | D14: 114.702 | E14: 114.702
C15: Liquefied Petroleum Gas (LPG) | D15: 3.428 | E15: 3.428
C16: Natural Gas | D16: 56515.751 | E16: 56515.751
C17: Propane | D17: 11.957 | E17: 11.957
C18: Fertilizer | D18: 2.352 | E18: 2.352
C19: Refrigerant | D19: 163.632 | E19: 163.632
B20: Scope 1 Total | D20: 57269.823 | E20: 57269.823
B21: Scope 2 | C21: Electric Power | D21: 26570.229 | E21: 31037.694
C22: Steam | D22: 4744.888 | E22: 4744.888
B23: Scope 2 Total | D23: 31315.117 | E23: 35782.582
B24: Scope 3 | C24: Hazardous Waste | D24: 115.996 | E24: 115.996
C25: Hazardous Waste - Recycled | D25: 0.024 | E25: 0.024
C26: Non-Hazardous Waste | D26: 995.21 | E26: 995.21
C27: Non-Hazardous Waste - Recycling | D27: 2.024 | E27: 2.024
C28: Solid Waste | D28: 0 | E28: 0
C29: Waste | D29: 379.116 | E29: 379.116
B30: Scope 3 Total | D30: 1492.37 | E30: 1492.37
B31: Grand Total | D31: 90077.31 | E31: 94544.775
B35: Year | C35: 2023
B37: Sum of Usage
B38: Scope | C38: Source | D38: UOM | E38: Total
B39: Scope 1 | C39: Diesel | D39: MWh | E39: 1052.0066
C40: Diesel - Clear Diesel | D40: gallons | E40: 3588
C41: Dry Ice | D41: metric tons | E41: 42.15687
C42: Fertilizer | D42: mtons CO2-e | E42: 2.352
C43: Gas Oil | D43: MWh | E43: 7.6787
C44: Gasoline | D44: MWh | E44: 95.526332
C45: Gasoline - 87 octane (regular) | D45: MWh | E45: 520.50072
C46: Gasoline - 95 octane (premium) | D46: gallons | E46: 14441.48
C47: Liquefied Petroleum Gas (LPG) | D47: MWh | E47: 15.615
...

Sheet Results by Site
B2: Year | C2: 2023
B3: Market Based Emissions 2023
B4: Sum of Total CO2e Emissions (Market Based) (mtons CO2-e) | C4: Scope
B5: Site Name | C5: Scope 1 | D5: Scope 2 | E5: Scope 3 | F5: Grand Total
B6: Agrinsa | C6: 150.545 | D6: 1733.606 | F6: 1884.151
B7: Barcelona | C7: 64.488 | F7: 64.488
B8: Bogota | C8: 21.9 | D8: 3.54 | F8: 25.44
B9: Buenos Aires | C9: 0 | F9: 0
B10: Carnegie, PA | C10: 1190.11 | D10: 739.945 | E10: 322.57 | F10: 2252.625
B11: Chicago, IL | C11: 44646.434 | D11: 9051.999 | E11: 0 | F11: 53698.433
B12: Dateland | C12: 574.678 | D12: 1529.021 | E12: 198.828 | F12: 2302.527
B13: Deerfield | D13: 14.932 | F13: 14.932
B14: Englewood, OH | C14: 168.533 | D14: 800.736 | E14: 389.86 | F14: 1359.129
B15: Fairfield | C15: 97.85 | D15: 116.76 | E15: 0.448 | F15: 215.058
B16: Granollers | D16: 7.345 | F16: 7.345
B17: Gurnee, IL | C17: 10079.744 | D17: 3914.803 | E17: 8.733 | F17: 14003.28
B18: Les Borges | C18: 74.544 | D18: 39.81 | E18: 51.895 | F18: 166.249
B19: Leuna | C19: 142.251 | D19: 13126.913 | E19: 226.086 | F19: 13495.25
B20: Linden, NJ | D20: 16.545 | E20: 9.71 | F20: 26.255
B21: Mexico City | D21: 3.669 | F21: 3.669
B22: Mumbai | D22: 0.036 | F22: 0.036
B23: Pittsburgh, PA | C23: 44.852 | D23: 60.468 | E23: 29.024 | F23: 134.344
B24: Santiago | D24: 4.536 | F24: 4.536
B25: Sao Paulo | D25: 1.394 | F25: 1.394
B26: Shanghai | D26: 20.649 | F26: 20.649
B27: South Africa | D27: 26.596 | E27: 149.856 | F27: 176.452
B28: Tucson | C28: 13.894 | D28: 55.056 | E28: 105.36 | F28: 174.31
B29: Warren, NJ | D29: 46.758 | E29: 0 | F29: 46.758
B30: Grand Total | C30: 57269.823 | D30: 31315.117 | E30: 1492.37 | F30: 90077.31
B34: Electric Power | F34: Natural Gas
B35: Source | C35: Electric Power | F35: Source | G35: Natural Gas
B36: Year | C36: 2023 | F36: Year | G36: 2023
B38: Sum of Usage | C38: UOM | F38: Sum of Usage | G38: UOM
B39: Site Name | C39: MWh | F39: Site Name | G39: MWh
B40: Agrinsa | C40: 5606.83 | F40: Barcelona | G40: 70.1864
B41: Bogota | C41: 23.16 | F41: Bogota | G41: 0
B42: Carnegie, PA | C42: 1556.618 | F42: Buenos Aires | G42: 0
B43: Chicago, IL | C43: 31279.376 | F43: Carnegie, PA | G43: 6566.368
B44: Dateland | C44: 4500.5525 | F44: Chicago, IL | G44: 245748.82
B45: Deerfield | C45: 51.6 | F45: Dateland | G45: 1767.1306
...

Sheet RA - Emissions Report
A3: Report Name: | B3: Preview
A4: Custom Report: | B4: Emissions
A5: Client: | B5: Vantage Specialty Chemicals
A6: Level: | B6: Site
A7: Date Range: | B7: 1/1/2023 to 12/31/2023
A8: CarbonMaps: | B8: Primary: Vantage Specialty Chemical Market-Based Carbon Map (Market-based), Secondary: Vantage Specialty Chemicals Location-Based CM (Location-based)
A11: Month | B11: Source | C11: Division | D11: Site Name | E11: Scope | F11: Address | G11: City | H11: State | I11: Country | J11: UOM | K11: Usage | L11: Total Cost (USD) | M11: Site Reference number | N11: Total CO2e Emissions (Market Based) (mtons CO2-e) | O11: CO2 Emissions (Primary) (mtons CO2-e) | P11: N2O Emissions (Primary) (mtons CO2-e) | Q11: CH4 Emissions (Primary) (mtons CO2-e) | R11: Total CO2e Emissions (Location-Based) (mtons CO2-e) | S11: CO2 Emissions (Secondary) (mtons CO2-e) | T11: N2O Emissions (Secondary) (mtons CO2-e) | U11: CH4 Emissions (Secondary) (mtons CO2-e) | V11: Year
A12: 44927 | B12: Diesel | C12: Farm | D12: Agrinsa | E12: Scope 1 | F12: RUTA 60 Km 12220 - Aimogasta | G12: La Rioja | H12: ARG | I12: Argentina | J12: MWh | K12: 11.528083 | N12: 2.698 | O12: 2.661364 | P12: 0.036391 | Q12: 0.000333 | R12: 2.698 | S12: 2.661364 | T12: 0.036391 | U12: 0.000333 | V12: =YEAR(A12) -> 2023
A13: 44927 | B13: Fertilizer | C13: Farm | D13: Agrinsa | E13: Scope 1 | F13: RUTA 60 Km 12220 - Aimogasta | G13: La Rioja | H13: ARG | I13: Argentina | J13: mtons CO2-e | K13: 0.03 | N13: 0.03 | O13: 0.03 | R13: =N13 -> 0.03 | V13: =YEAR(A13) -> 2023
A14: 44927 | B14: Gasoline | C14: Farm | D14: Agrinsa | E14: Scope 1 | F14: RUTA 60 Km 12220 - Aimogasta | G14: La Rioja | H14: ARG | I14: Argentina | J14: MWh | K14: 3.51218 | L14: 167.48 | N14: 0.761 | O14: 0.756151 | P14: 0.002195 | Q14: 0.003115 | R14: 0.761 | S14: 0.756151 | T14: 0.002195 | U14: 0.003115 | V14: =YEAR(A14) -> 2023
A15: 44927 | B15: Gasoline - 95 octane (premium) | C15: Farm | D15: Agrinsa | E15: Scope 1 | F15: RUTA 60 Km 12220 - Aimogasta | G15: La Rioja | H15: ARG | I15: Argentina | J15: gallons | K15: 964.76 | N15: 7.663 | O15: 7.609117 | P15: 0.022084 | Q15: 0.031343 | R15: 7.663 | S15: 7.609117 | T15: 0.022084 | U15: 0.031343 | V15: =YEAR(A15) -> 2023
A16: 44958 | B16: Diesel | C16: Farm | D16: Agrinsa | E16: Scope 1 | F16: RUTA 60 Km 12220 - Aimogasta | G16: La Rioja | H16: ARG | I16: Argentina | J16: MWh | K16: 8.745009 | N16: 2.047 | O16: 2.018866 | P16: 0.027606 | Q16: 0.000252 | R16: 2.047 | S16: 2.018866 | T16: 0.027606 | U16: 0.000252 | V16: =YEAR(A16) -> 2023
A17: 44958 | B17: Fertilizer | C17: Farm | D17: Agrinsa | E17: Scope 1 | F17: RUTA 60 Km 12220 - Aimogasta | G17: La Rioja | H17: ARG | I17: Argentina | J17: mtons CO2-e | K17: 0.03 | N17: 0.03 | O17: 0.03 | R17: =N17 -> 0.03 | V17: =YEAR(A17) -> 2023
A18: 44958 | B18: Gasoline | C18: Farm | D18: Agrinsa | E18: Scope 1 | F18: RUTA 60 Km 12220 - Aimogasta | G18: La Rioja | H18: ARG | I18: Argentina | J18: MWh | K18: 3.71954 | L18: 177.26 | N18: 0.806 | O18: 0.800795 | P18: 0.002324 | Q18: 0.003299 | R18: 0.806 | S18: 0.800795 | T18: 0.002324 | U18: 0.003299 | V18: =YEAR(A18) -> 2023
A19: 44958 | B19: Gasoline - 95 octane (premium) | C19: Farm | D19: Agrinsa | E19: Scope 1 | F19: RUTA 60 Km 12220 - Aimogasta | G19: La Rioja | H19: ARG | I19: Argentina | J19: gallons | K19: 721.55 | N19: 5.731 | O19: 5.690906 | P19: 0.016516 | Q19: 0.023442 | R19: 5.731 | S19: 5.690906 | T19: 0.016516 | U19: 0.023442 | V19: =YEAR(A19) -> 2023
A20: 44986 | B20: Diesel | C20: Farm | D20: Agrinsa | E20: Scope 1 | F20: RUTA 60 Km 12220 - Aimogasta | G20: La Rioja | H20: ARG | I20: Argentina | J20: MWh | K20: 90.954515 | N20: 21.287 | O20: 20.99769 | P20: 0.287119 | Q20: 0.002625 | R20: 21.287 | S20: 20.99769 | T20: 0.287119 | U20: 0.002625 | V20: =YEAR(A20) -> 2023
A21: 44986 | B21: Fertilizer | C21: Farm | D21: Agrinsa | E21: Scope 1 | F21: RUTA 60 Km 12220 - Aimogasta | G21: La Rioja | H21: ARG | I21: Argentina | J21: mtons CO2-e | K21: 0.03 | N21: 0.03 | O21: 0.03 | R21: =N21 -> 0.03 | V21: =YEAR(A21) -> 2023
A22: 44986 | B22: Gasoline | C22: Farm | D22: Agrinsa | E22: Scope 1 | F22: RUTA 60 Km 12220 - Aimogasta | G22: La Rioja | H22: ARG | I22: Argentina | J22: MWh | K22: 3.13276 | L22: 182.48 | N22: 0.679 | O22: 0.674465 | P22: 0.001957 | Q22: 0.002778 | R22: 0.679 | S22: 0.674465 | T22: 0.001957 | U22: 0.002778 | V22: =YEAR(A22) -> 2023
A23: 44986 | B23: Gasoline - 95 octane (premium) | C23: Farm | D23: Agrinsa | E23: Scope 1 | F23: RUTA 60 Km 12220 - Aimogasta | G23: La Rioja | H23: ARG | I23: Argentina | J23: gallons | K23: 1017.44 | N23: 8.081 | O23: 8.024607 | P23: 0.023289 | Q23: 0.033055 | R23: 8.081 | S23: 8.024607 | T23: 0.023289 | U23: 0.033055 | V23: =YEAR(A23) -> 2023
A24: 45017 | B24: Diesel | C24: Farm | D24: Agrinsa | E24: Scope 1 | F24: RUTA 60 Km 12220 - Aimogasta | G24: La Rioja | H24: ARG | I24: Argentina | J24: MWh | K24: 73.392018 | N24: 17.177 | O24: 16.943225 | P24: 0.231679 | Q24: 0.002118 | R24: 17.177 | S24: 16.943225 | T24: 0.231679 | U24: 0.002118 | V24: =YEAR(A24) -> 2023
A25: 45017 | B25: Fertilizer | C25: Farm | D25: Agrinsa | E25: Scope 1 | F25: RUTA 60 Km 12220 - Aimogasta | G25: La Rioja | H25: ARG | I25: Argentina | J25: mtons CO2-e | K25: 0.03 | N25: 0.03 | O25: 0.03 | R25: =N25 -> 0.03 | V25: =YEAR(A25) -> 2023
A26: 45017 | B26: Gasoline | C26: Farm | D26: Agrinsa | E26: Scope 1 | F26: RUTA 60 Km 12220 - Aimogasta | G26: La Rioja | H26: ARG | I26: Argentina | J26: MWh | K26: 3.32086 | L26: 193.9 | N26: 0.72 | O26: 0.714961 | P26: 0.002075 | Q26: 0.002945 | R26: 0.72 | S26: 0.714961 | T26: 0.002075 | U26: 0.002945 | V26: =YEAR(A26) -> 2023
A27: 45017 | B27: Gasoline - 95 octane (premium) | C27: Farm | D27: Agrinsa | E27: Scope 1 | F27: RUTA 60 Km 12220 - Aimogasta | G27: La Rioja | H27: ARG | I27: Argentina | J27: gallons | K27: 1118.82 | N27: 8.886 | O27: 8.824197 | P27: 0.02561 | Q27: 0.036348 | R27: 8.886 | S27: 8.824197 | T27: 0.02561 | U27: 0.036348 | V27: =YEAR(A27) -> 2023
A28: 45047 | B28: Diesel | C28: Farm | D28: Agrinsa | E28: Scope 1 | F28: RUTA 60 Km 12220 - Aimogasta | G28: La Rioja | H28: ARG | I28: Argentina | J28: MWh | K28: 26.547276 | N28: 6.213 | O28: 6.128684 | P28: 0.083803 | Q28: 0.000766 | R28: 6.213 | S28: 6.128684 | T28: 0.083803 | U28: 0.000766 | V28: =YEAR(A28) -> 2023
A29: 45047 | B29: Fertilizer | C29: Farm | D29: Agrinsa | E29: Scope 1 | F29: RUTA 60 Km 12220 - Aimogasta | G29: La Rioja | H29: ARG | I29: Argentina | J29: mtons CO2-e | K29: 0.03 | N29: 0.03 | O29: 0.03 | R29: =N29 -> 0.03 | V29: =YEAR(A29) -> 2023
A30: 45047 | B30: Gasoline | C30: Farm | D30: Agrinsa | E30: Scope 1 | F30: RUTA 60 Km 12220 - Aimogasta | G30: La Rioja | H30: ARG | I30: Argentina | J30: MWh | K30: 3.54996 | L30: 273.39 | N30: 0.77 | O30: 0.764285 | P30: 0.002218 | Q30: 0.003148 | R30: 0.77 | S30: 0.764285 | T30: 0.002218 | U30: 0.003148 | V30: =YEAR(A30) -> 2023
A31: 45047 | B31: Gasoline - 95 octane (premium) | C31: Farm | D31: Agrinsa | E31: Scope 1 | F31: RUTA 60 Km 12220 - Aimogasta | G31: La Rioja | H31: ARG | I31: Argentina | J31: gallons | K31: 991.97 | N31: 7.879 | O31: 7.823724 | P31: 0.022706 | Q31: 0.032227 | R31: 7.879 | S31: 7.823724 | T31: 0.022706 | U31: 0.032227 | V31: =YEAR(A31) -> 2023
A32: 45078 | B32: Diesel | C32: Farm | D32: Agrinsa | E32: Scope 1 | F32: RUTA 60 Km 12220 - Aimogasta | G32: La Rioja | H32: ARG | I32: Argentina | J32: MWh | K32: 3.430013 | N32: 0.803 | O32: 0.79185 | P32: 0.010828 | Q32: 9.9e-05 | R32: 0.803 | S32: 0.79185 | T32: 0.010828 | U32: 9.9e-05 | V32: =YEAR(A32) -> 2023
A33: 45078 | B33: Fertilizer | C33: Farm | D33: Agrinsa | E33: Scope 1 | F33: RUTA 60 Km 12220 - Aimogasta | G33: La Rioja | H33: ARG | I33: Argentina | J33: mtons CO2-e | K33: 0.03 | N33: 0.03 | O33: 0.03 | R33: =N33 -> 0.03 | V33: =YEAR(A33) -> 2023
A34: 45078 | B34: Gasoline | C34: Farm | D34: Agrinsa | E34: Scope 1 | F34: RUTA 60 Km 12220 - Aimogasta | G34: La Rioja | H34: ARG | I34: Argentina | J34: MWh | K34: 5.28346 | L34: 293.8 | N34: 1.145 | O34: 1.137497 | P34: 0.003301 | Q34: 0.004686 | R34: 1.145 | S34: 1.137497 | T34: 0.003301 | U34: 0.004686 | V34: =YEAR(A34) -> 2023
A35: 45078 | B35: Gasoline - 95 octane (premium) | C35: Farm | D35: Agrinsa | E35: Scope 1 | F35: RUTA 60 Km 12220 - Aimogasta | G35: La Rioja | H35: ARG | I35: Argentina | J35: gallons | K35: 0 | N35: 0 | O35: 0 | P35: 0 | Q35: 0 | R35: 0 | S35: 0 | T35: 0 | U35: 0 | V35: =YEAR(A35) -> 2023
A36: 45108 | B36: Diesel | C36: Farm | D36: Agrinsa | E36: Scope 1 | F36: RUTA 60 Km 12220 - Aimogasta | G36: La Rioja | H36: ARG | I36: Argentina | J36: MWh | K36: 4.645937 | N36: 1.087 | O36: 1.072557 | P36: 0.014666 | Q36: 0.000134 | R36: 1.087 | S36: 1.072557 | T36: 0.014666 | U36: 0.000134 | V36: =YEAR(A36) -> 2023
A37: 45108 | B37: Fertilizer | C37: Farm | D37: Agrinsa | E37: Scope 1 | F37: RUTA 60 Km 12220 - Aimogasta | G37: La Rioja | H37: ARG | I37: Argentina | J37: mtons CO2-e | K37: 0.03 | N37: 0.03 | O37: 0.03 | R37: =N37 -> 0.03 | V37: =YEAR(A37) -> 2023
A38: 45108 | B38: Gasoline | C38: Farm | D38: Agrinsa | E38: Scope 1 | F38: RUTA 60 Km 12220 - Aimogasta | G38: La Rioja | H38: ARG | I38: Argentina | J38: MWh | K38: 6.64514 | L38: 365.84 | N38: 1.441 | O38: 1.430659 | P38: 0.004152 | Q38: 0.005893 | R38: 1.441 | S38: 1.430659 | T38: 0.004152 | U38: 0.005893 | V38: =YEAR(A38) -> 2023
A39: 45108 | B39: Gasoline - 95 octane (premium) | C39: Farm | D39: Agrinsa | E39: Scope 1 | F39: RUTA 60 Km 12220 - Aimogasta | G39: La Rioja | H39: ARG | I39: Argentina | J39: gallons | K39: 27.96 | N39: 0.222 | O39: 0.220522 | P39: 0.00064 | Q39: 0.000908 | R39: 0.222 | S39: 0.220522 | T39: 0.00064 | U39: 0.000908 | V39: =YEAR(A39) -> 2023
A40: 45139 | B40: Diesel | C40: Farm | D40: Agrinsa | E40: Scope 1 | F40: RUTA 60 Km 12220 - Aimogasta | G40: La Rioja | H40: ARG | I40: Argentina | J40: MWh | K40: 4.561647 | N40: 1.068 | O40: 1.053098 | P40: 0.0144 | Q40: 0.000132 | R40: 1.068 | S40: 1.053098 | T40: 0.0144 | U40: 0.000132 | V40: =YEAR(A40) -> 2023
A41: 45139 | B41: Fertilizer | C41: Farm | D41: Agrinsa | E41: Scope 1 | F41: RUTA 60 Km 12220 - Aimogasta | G41: La Rioja | H41: ARG | I41: Argentina | J41: mtons CO2-e | K41: 0.03 | N41: 0.03 | O41: 0.03 | R41: =N41 -> 0.03 | V41: =YEAR(A41) -> 2023
A42: 45139 | B42: Gasoline | C42: Farm | D42: Agrinsa | E42: Scope 1 | F42: RUTA 60 Km 12220 - Aimogasta | G42: La Rioja | H42: ARG | I42: Argentina | J42: MWh | K42: 6.72146 | L42: 370.46 | N42: 1.457 | O42: 1.44709 | P42: 0.0042 | Q42: 0.005961 | R42: 1.457 | S42: 1.44709 | T42: 0.0042 | U42: 0.005961 | V42: =YEAR(A42) -> 2023
A43: 45139 | B43: Gasoline - 95 octane (premium) | C43: Farm | D43: Agrinsa | E43: Scope 1 | F43: RUTA 60 Km 12220 - Aimogasta | G43: La Rioja | H43: ARG | I43: Argentina | J43: gallons | K43: 1.78 | N43: 0.014 | O43: 0.014039 | P43: 4.1e-05 | Q43: 5.8e-05 | R43: 0.014 | S43: 0.014039 | T43: 4.1e-05 | U43: 5.8e-05 | V43: =YEAR(A43) -> 2023
A44: 45170 | B44: Diesel | C44: Farm | D44: Agrinsa | E44: Scope 1 | F44: RUTA 60 Km 12220 - Aimogasta | G44: La Rioja | H44: ARG | I44: Argentina | J44: MWh | K44: 5.227162 | L44: 481.2612 | N44: 1.223 | O44: 1.206739 | P44: 0.016501 | Q44: 0.000151 | R44: 1.223 | S44: 1.206739 | T44: 0.016501 | U44: 0.000151 | V44: =YEAR(A44) -> 2023
...

Sheet RA- Water Report
A3: Report Name: | B3: Preview
A4: Custom Report: | B4: Cost and Usage
A5: Service: | B5: Water
A6: Client: | B6: Vantage Specialty Chemicals
A7: Level: | B7: Site
A8: Filters: | B8: Site Status:Active
A9: Date Range: | B9: 1/1/2023 to 12/31/2023
A10: Units of Measure: | B10: Currency:USD, Water:gallons
A12: Service Month | B12: Site Name | C12: Total Cost (USD) | D12: Total Water Usage (gallons) | E12: Unit Cost | F12: Year
A13: 44927 | B13: Agrinsa | C13: 80091.85 | D13: 2.2208429e+08 | E13: 0.0003606371 | F13: =YEAR(A13) -> 2023
A14: 44927 | B14: Barcelona | F14: =YEAR(A14) -> 2023
A15: 44927 | B15: Bogota | F15: =YEAR(A15) -> 2023
A16: 44927 | B16: Buenos Aires | F16: =YEAR(A16) -> 2023
A17: 44927 | B17: Carnegie, PA | D17: 171500 | F17: =YEAR(A17) -> 2023
A18: 44927 | B18: Chicago, IL | F18: =YEAR(A18) -> 2023
A19: 44927 | B19: Dateland | F19: =YEAR(A19) -> 2023
A20: 44927 | B20: Deerfield | F20: =YEAR(A20) -> 2023
A21: 44927 | B21: Englewood, OH | C21: 538.895 | D21: 95050 | E21: 0.0056695949 | F21: =YEAR(A21) -> 2023
A22: 44927 | B22: Fairfield | F22: =YEAR(A22) -> 2023
A23: 44927 | B23: Granollers | F23: =YEAR(A23) -> 2023
A24: 44927 | B24: Gurnee, IL | F24: =YEAR(A24) -> 2023
A25: 44927 | B25: Les Borges | D25: 0 | F25: =YEAR(A25) -> 2023
A26: 44927 | B26: Leuna | F26: =YEAR(A26) -> 2023
A27: 44927 | B27: Linden, NJ | D27: 4000 | F27: =YEAR(A27) -> 2023
A28: 44927 | B28: Mexico City | F28: =YEAR(A28) -> 2023
A29: 44927 | B29: Mumbai | F29: =YEAR(A29) -> 2023
A30: 44927 | B30: Pittsburgh, PA | F30: =YEAR(A30) -> 2023
A31: 44927 | B31: Santiago | F31: =YEAR(A31) -> 2023
A32: 44927 | B32: Sao Paulo | D32: 264.17205 | F32: =YEAR(A32) -> 2023
A33: 44927 | B33: Shanghai | C33: 10.667511 | D33: 3170.0646 | E33: 0.0033650768 | F33: =YEAR(A33) -> 2023
A34: 44927 | B34: South Africa | F34: =YEAR(A34) -> 2023
A35: 44927 | B35: Tucson | D35: 1496.1039 | F35: =YEAR(A35) -> 2023
A36: 44927 | B36: Warren, NJ | F36: =YEAR(A36) -> 2023
A37: 44958 | B37: Agrinsa | C37: 81587.75 | D37: 1.8607986e+08 | E37: 0.0004384555 | F37: =YEAR(A37) -> 2023
A38: 44958 | B38: Barcelona | F38: =YEAR(A38) -> 2023
A39: 44958 | B39: Bogota | F39: =YEAR(A39) -> 2023
A40: 44958 | B40: Buenos Aires | F40: =YEAR(A40) -> 2023
A41: 44958 | B41: Carnegie, PA | D41: 171000 | F41: =YEAR(A41) -> 2023
A42: 44958 | B42: Chicago, IL | F42: =YEAR(A42) -> 2023
A43: 44958 | B43: Dateland | F43: =YEAR(A43) -> 2023
...

Sheet MB-CarbonMap
A1: Vantage Specialty Chemicals | B1: Vantage Specialty Chemicals | C1: Vantage Specialty Chemicals | D1: Vantage Specialty Chemicals | E1: Vantage Specialty Chemicals | F1: Vantage Specialty Chemicals | G1: Vantage Specialty Chemicals | H1: Vantage Specialty Chemicals | I1: Vantage Specialty Chemicals | J1: Vantage Specialty Chemicals | K1: Vantage Specialty Chemicals | L1: Vantage Specialty Chemicals | M1: Vantage Specialty Chemicals | N1: Vantage Specialty Chemicals | O1: Vantage Specialty Chemicals | P1: Vantage Specialty Chemicals | Q1: Vantage Specialty Chemicals | R1: Vantage Specialty Chemicals
A2: CarbonMap Details | B2: CarbonMap Details | C2: CarbonMap Details | D2: CarbonMap Details | E2: CarbonMap Details | F2: CarbonMap Details | G2: CarbonMap Details | H2: CarbonMap Details | I2: CarbonMap Details | J2: CarbonMap Details | K2: CarbonMap Details | L2: CarbonMap Details | M2: CarbonMap Details | N2: CarbonMap Details | O2: CarbonMap Details | P2: CarbonMap Details | Q2: CarbonMap Details | R2: CarbonMap Details
A3: Division/Group - All, Site(s) - All | B3: Division/Group - All, Site(s) - All | C3: Division/Group - All, Site(s) - All | D3: Division/Group - All, Site(s) - All | E3: Division/Group - All, Site(s) - All | F3: Division/Group - All, Site(s) - All | G3: Division/Group - All, Site(s) - All | H3: Division/Group - All, Site(s) - All | I3: Division/Group - All, Site(s) - All | J3: Division/Group - All, Site(s) - All | K3: Division/Group - All, Site(s) - All | L3: Division/Group - All, Site(s) - All | M3: Division/Group - All, Site(s) - All | N3: Division/Group - All, Site(s) - All | O3: Division/Group - All, Site(s) - All | P3: Division/Group - All, Site(s) - All | Q3: Division/Group - All, Site(s) - All | R3: Division/Group - All, Site(s) - All
A4: CarbonMap Name - Primary: Vantage Specialty Chemical Market-Based Carbon Map (Market-based),CarbonMap Version -CY 2023 | B4: CarbonMap Name - Primary: Vantage Specialty Chemical Market-Based Carbon Map (Market-based),CarbonMap Version -CY 2023 | C4: CarbonMap Name - Primary: Vantage Specialty Chemical Market-Based Carbon Map (Market-based),CarbonMap Version -CY 2023 | D4: CarbonMap Name - Primary: Vantage Specialty Chemical Market-Based Carbon Map (Market-based),CarbonMap Version -CY 2023 | E4: CarbonMap Name - Primary: Vantage Specialty Chemical Market-Based Carbon Map (Market-based),CarbonMap Version -CY 2023 | F4: CarbonMap Name - Primary: Vantage Specialty Chemical Market-Based Carbon Map (Market-based),CarbonMap Version -CY 2023 | G4: CarbonMap Name - Primary: Vantage Specialty Chemical Market-Based Carbon Map (Market-based),CarbonMap Version -CY 2023 | H4: CarbonMap Name - Primary: Vantage Specialty Chemical Market-Based Carbon Map (Market-based),CarbonMap Version -CY 2023 | I4: CarbonMap Name - Primary: Vantage Specialty Chemical Market-Based Carbon Map (Market-based),CarbonMap Version -CY 2023 | J4: CarbonMap Name - Primary: Vantage Specialty Chemical Market-Based Carbon Map (Market-based),CarbonMap Version -CY 2023 | K4: CarbonMap Name - Primary: Vantage Specialty Chemical Market-Based Carbon Map (Market-based),CarbonMap Version -CY 2023 | L4: CarbonMap Name - Primary: Vantage Specialty Chemical Market-Based Carbon Map (Market-based),CarbonMap Version -CY 2023 | M4: CarbonMap Name - Primary: Vantage Specialty Chemical Market-Based Carbon Map (Market-based),CarbonMap Version -CY 2023 | N4: CarbonMap Name - Primary: Vantage Specialty Chemical Market-Based Carbon Map (Market-based),CarbonMap Version -CY 2023 | O4: CarbonMap Name - Primary: Vantage Specialty Chemical Market-Based Carbon Map (Market-based),CarbonMap Version -CY 2023 | P4: CarbonMap Name - Primary: Vantage Specialty Chemical Market-Based Carbon Map (Market-based),CarbonMap Version -CY 2023 | Q4: CarbonMap Name - Primary: Vantage Specialty Chemical Market-Based Carbon Map (Market-based),CarbonMap Version -CY 2023 | R4: CarbonMap Name - Primary: Vantage Specialty Chemical Market-Based Carbon Map (Market-based),CarbonMap Version -CY 2023
A5: Note : all values CO2-e (The emission factors below are displayed as CO2-equivalents. Global Warming Potential (GWP) has been applied to the native pollutant emission factors.) | B5: Note : all values CO2-e (The emission factors below are displayed as CO2-equivalents. Global Warming Potential (GWP) has been applied to the native pollutant emission factors.) | C5: Note : all values CO2-e (The emission factors below are displayed as CO2-equivalents. Global Warming Potential (GWP) has been applied to the native pollutant emission factors.) | D5: Note : all values CO2-e (The emission factors below are displayed as CO2-equivalents. Global Warming Potential (GWP) has been applied to the native pollutant emission factors.) | E5: Note : all values CO2-e (The emission factors below are displayed as CO2-equivalents. Global Warming Potential (GWP) has been applied to the native pollutant emission factors.) | F5: Note : all values CO2-e (The emission factors below are displayed as CO2-equivalents. Global Warming Potential (GWP) has been applied to the native pollutant emission factors.) | G5: Note : all values CO2-e (The emission factors below are displayed as CO2-equivalents. Global Warming Potential (GWP) has been applied to the native pollutant emission factors.) | H5: Note : all values CO2-e (The emission factors below are displayed as CO2-equivalents. Global Warming Potential (GWP) has been applied to the native pollutant emission factors.) | I5: Note : all values CO2-e (The emission factors below are displayed as CO2-equivalents. Global Warming Potential (GWP) has been applied to the native pollutant emission factors.) | J5: Note : all values CO2-e (The emission factors below are displayed as CO2-equivalents. Global Warming Potential (GWP) has been applied to the native pollutant emission factors.) | K5: Note : all values CO2-e (The emission factors below are displayed as CO2-equivalents. Global Warming Potential (GWP) has been applied to the native pollutant emission factors.) | L5: Note : all values CO2-e (The emission factors below are displayed as CO2-equivalents. Global Warming Potential (GWP) has been applied to the native pollutant emission factors.) | M5: Note : all values CO2-e (The emission factors below are displayed as CO2-equivalents. Global Warming Potential (GWP) has been applied to the native pollutant emission factors.) | N5: Note : all values CO2-e (The emission factors below are displayed as CO2-equivalents. Global Warming Potential (GWP) has been applied to the native pollutant emission factors.) | O5: Note : all values CO2-e (The emission factors below are displayed as CO2-equivalents. Global Warming Potential (GWP) has been applied to the native pollutant emission factors.) | P5: Note : all values CO2-e (The emission factors below are displayed as CO2-equivalents. Global Warming Potential (GWP) has been applied to the native pollutant emission factors.) | Q5: Note : all values CO2-e (The emission factors below are displayed as CO2-equivalents. Global Warming Potential (GWP) has been applied to the native pollutant emission factors.) | R5: Note : all values CO2-e (The emission factors below are displayed as CO2-equivalents. Global Warming Potential (GWP) has been applied to the native pollutant emission factors.)
A6: Division | B6: Site | C6: Region/Utility | D6: Scope | E6: Frequency | F6: Source | G6: Units | H6: Emission Factor Set | I6: Emission Factor Version | J6: CO2 | K6: CH4 | L6: N2O | M6: HFC | N6: PFC | O6: SF6 | P6: NF3 | Q6: Comments | R6: As of Year
A7: Farm | B7: Agrinsa | C7: Non Regional | D7: Scope 1 | E7: Monthly | F7: Diesel | G7: grams/liters | H7: Department for Environment Food and Rural Affairs (DEFRA) | I7: 2023 Guideline to DEFRA | J7: 2478.87 | K7: 0.30992 | L7: 33.89568 | Q7: The 2023 GHG Conversion factors are suitable for all UK based organisations, and international organisations with a UK operations footprint. Expiration Date: 7/31/2024 | R7: 2023
A8: Farm | B8: Dateland | C8: Non Regional | D8: Scope 1 | E8: Monthly | F8: Diesel | G8: grams/liters | H8: Department for Environment Food and Rural Affairs (DEFRA) | I8: 2023 Guideline to DEFRA | J8: 2478.87 | K8: 0.30992 | L8: 33.89568 | Q8: The 2023 GHG Conversion factors are suitable for all UK based organisations, and international organisations with a UK operations footprint. Expiration Date: 7/31/2024 | R8: 2023
A9: Food | B9: Pittsburgh, PA | C9: Non Regional | D9: Scope 1 | E9: Monthly | F9: Diesel | G9: grams/liters | H9: Department for Environment Food and Rural Affairs (DEFRA) | I9: 2023 Guideline to DEFRA | J9: 2478.87 | K9: 0.30992 | L9: 33.89568 | Q9: The 2023 GHG Conversion factors are suitable for all UK based organisations, and international organisations with a UK operations footprint. Expiration Date: 7/31/2024 | R9: 2023
A10: Manufacturing | B10: Carnegie, PA | C10: Non Regional | D10: Scope 1 | E10: Monthly | F10: Diesel | G10: grams/liters | H10: Department for Environment Food and Rural Affairs (DEFRA) | I10: 2023 Guideline to DEFRA | J10: 2478.87 | K10: 0.30992 | L10: 33.89568 | Q10: The 2023 GHG Conversion factors are suitable for all UK based organisations, and international organisations with a UK operations footprint. Expiration Date: 7/31/2024 | R10: 2023
A11: Manufacturing | B11: Chicago, IL | C11: Non Regional | D11: Scope 1 | E11: Monthly | F11: Diesel | G11: grams/liters | H11: Department for Environment Food and Rural Affairs (DEFRA) | I11: 2023 Guideline to DEFRA | J11: 2478.87 | K11: 0.30992 | L11: 33.89568 | Q11: The 2023 GHG Conversion factors are suitable for all UK based organisations, and international organisations with a UK operations footprint. Expiration Date: 7/31/2024 | R11: 2023
A12: Manufacturing | B12: Englewood, OH | C12: Non Regional | D12: Scope 1 | E12: Monthly | F12: Diesel | G12: grams/liters | H12: Department for Environment Food and Rural Affairs (DEFRA) | I12: 2023 Guideline to DEFRA | J12: 2478.87 | K12: 0.30992 | L12: 33.89568 | Q12: The 2023 GHG Conversion factors are suitable for all UK based organisations, and international organisations with a UK operations footprint. Expiration Date: 7/31/2024 | R12: 2023
A13: Manufacturing | B13: Fairfield | C13: Non Regional | D13: Scope 1 | E13: Monthly | F13: Diesel | G13: grams/liters | H13: Department for Environment Food and Rural Affairs (DEFRA) | I13: 2023 Guideline to DEFRA | J13: 2478.87 | K13: 0.30992 | L13: 33.89568 | Q13: The 2023 GHG Conversion factors are suitable for all UK based organisations, and international organisations with a UK operations footprint. Expiration Date: 7/31/2024 | R13: 2023
A14: Manufacturing | B14: Gurnee, IL | C14: Non Regional | D14: Scope 1 | E14: Monthly | F14: Diesel | G14: grams/liters | H14: Department for Environment Food and Rural Affairs (DEFRA) | I14: 2023 Guideline to DEFRA | J14: 2478.87 | K14: 0.30992 | L14: 33.89568 | Q14: The 2023 GHG Conversion factors are suitable for all UK based organisations, and international organisations with a UK operations footprint. Expiration Date: 7/31/2024 | R14: 2023
A15: Manufacturing | B15: Les Borges | C15: Non Regional | D15: Scope 1 | E15: Monthly | F15: Diesel | G15: grams/liters | H15: Department for Environment Food and Rural Affairs (DEFRA) | I15: 2023 Guideline to DEFRA | J15: 2478.87 | K15: 0.30992 | L15: 33.89568 | Q15: The 2023 GHG Conversion factors are suitable for all UK based organisations, and international organisations with a UK operations footprint. Expiration Date: 7/31/2024 | R15: 2023
A16: Manufacturing | B16: Leuna | C16: Non Regional | D16: Scope 1 | E16: Monthly | F16: Diesel | G16: grams/liters | H16: Department for Environment Food and Rural Affairs (DEFRA) | I16: 2023 Guideline to DEFRA | J16: 2478.87 | K16: 0.30992 | L16: 33.89568 | Q16: The 2023 GHG Conversion factors are suitable for all UK based organisations, and international organisations with a UK operations footprint. Expiration Date: 7/31/2024 | R16: 2023
A17: Manufacturing | B17: Tucson | C17: Non Regional | D17: Scope 1 | E17: Monthly | F17: Diesel | G17: grams/liters | H17: Department for Environment Food and Rural Affairs (DEFRA) | I17: 2023 Guideline to DEFRA | J17: 2478.87 | K17: 0.30992 | L17: 33.89568 | Q17: The 2023 GHG Conversion factors are suitable for all UK based organisations, and international organisations with a UK operations footprint. Expiration Date: 7/31/2024 | R17: 2023
A18: Office | B18: Barcelona | C18: Non Regional | D18: Scope 1 | E18: Monthly | F18: Diesel | G18: grams/liters | H18: Department for Environment Food and Rural Affairs (DEFRA) | I18: 2023 Guideline to DEFRA | J18: 2478.87 | K18: 0.30992 | L18: 33.89568 | Q18: The 2023 GHG Conversion factors are suitable for all UK based organisations, and international organisations with a UK operations footprint. Expiration Date: 7/31/2024 | R18: 2023
... A30: Warehouse | B30: South Africa | C30: Non Regional | D30: Scope 1 | E30: Monthly | F30: Diesel | G30: grams/liters | H30: Department for Environment Food and Rural Affairs (DEFRA) | I30: 2023 Guideline to DEFRA | J30: 2478.87 | K30: 0.30992 | L30: 33.89568 | Q30: The 2023 GHG Conversion factors are suitable for all UK based organisations, and international organisations with a UK operations footprint. Expiration Date: 7/31/2024 | R30: 2023
A31: Farm | B31: Agrinsa | C31: - | D31: Scope 1 | E31: Monthly | F31: Diesel - Clear Diesel | G31: grams/liters | H31: Manual | I31: Manual | J31: 2478.87 | K31: 0.30992 | L31: 33.89568 | Q31: Manual input from DEFRA Diesel factors 2023 | R31: -
A32: Farm | B32: Dateland | C32: - | D32: Scope 1 | E32: Monthly | F32: Diesel - Clear Diesel | G32: grams/liters | H32: Manual | I32: Manual | J32: 2478.87 | K32: 0.30992 | L32: 33.89568 | Q32: Manual input from DEFRA Diesel factors 2023 | R32: -
A33: Food | B33: Pittsburgh, PA | C33: - | D33: Scope 1 | E33: Monthly | F33: Diesel - Clear Diesel | G33: grams/liters | H33: Manual | I33: Manual | J33: 2478.87 | K33: 0.30992 | L33: 33.89568 | Q33: Manual input from DEFRA Diesel factors 2023 | R33: -
A34: Manufacturing | B34: Carnegie, PA | C34: - | D34: Scope 1 | E34: Monthly | F34: Diesel - Clear Diesel | G34: grams/liters | H34: Manual | I34: Manual | J34: 2478.87 | K34: 0.30992 | L34: 33.89568 | Q34: Manual input from DEFRA Diesel factors 2023 | R34: -
A35: Manufacturing | B35: Chicago, IL | C35: - | D35: Scope 1 | E35: Monthly | F35: Diesel - Clear Diesel | G35: grams/liters | H35: Manual | I35: Manual | J35: 2478.87 | K35: 0.30992 | L35: 33.89568 | Q35: Manual input from DEFRA Diesel factors 2023 | R35: -
A36: Manufacturing | B36: Englewood, OH | C36: - | D36: Scope 1 | E36: Monthly | F36: Diesel - Clear Diesel | G36: grams/liters | H36: Manual | I36: Manual | J36: 2478.87 | K36: 0.30992 | L36: 33.89568 | Q36: Manual input from DEFRA Diesel factors 2023 | R36: -
A37: Manufacturing | B37: Fairfield | C37: - | D37: Scope 1 | E37: Monthly | F37: Diesel - Clear Diesel | G37: grams/liters | H37: Manual | I37: Manual | J37: 2478.87 | K37: 0.30992 | L37: 33.89568 | Q37: Manual input from DEFRA Diesel factors 2023 | R37: -
A38: Manufacturing | B38: Gurnee, IL | C38: - | D38: Scope 1 | E38: Monthly | F38: Diesel - Clear Diesel | G38: grams/liters | H38: Manual | I38: Manual | J38: 2478.87 | K38: 0.30992 | L38: 33.89568 | Q38: Manual input from DEFRA Diesel factors 2023 | R38: -
A39: Manufacturing | B39: Les Borges | C39: - | D39: Scope 1 | E39: Monthly | F39: Diesel - Clear Diesel | G39: grams/liters | H39: Manual | I39: Manual | J39: 2478.87 | K39: 0.30992 | L39: 33.89568 | Q39: Manual input from DEFRA Diesel factors 2023 | R39: -
A40: Manufacturing | B40: Leuna | C40: - | D40: Scope 1 | E40: Monthly | F40: Diesel - Clear Diesel | G40: grams/liters | H40: Manual | I40: Manual | J40: 2478.87 | K40: 0.30992 | L40: 33.89568 | Q40: Manual input from DEFRA Diesel factors 2023 | R40: -
A41: Manufacturing | B41: Tucson | C41: - | D41: Scope 1 | E41: Monthly | F41: Diesel - Clear Diesel | G41: grams/liters | H41: Manual | I41: Manual | J41: 2478.87 | K41: 0.30992 | L41: 33.89568 | Q41: Manual input from DEFRA Diesel factors 2023 | R41: -
A42: Office | B42: Barcelona | C42: - | D42: Scope 1 | E42: Monthly | F42: Diesel - Clear Diesel | G42: grams/liters | H42: Manual | I42: Manual | J42: 2478.87 | K42: 0.30992 | L42: 33.89568 | Q42: Manual input from DEFRA Diesel factors 2023 | R42: -
... A54: Warehouse | B54: South Africa | C54: - | D54: Scope 1 | E54: Monthly | F54: Diesel - Clear Diesel | G54: grams/liters | H54: Manual | I54: Manual | J54: 2478.87 | K54: 0.30992 | L54: 33.89568 | Q54: Manual input from DEFRA Diesel factors 2023 | R54: -
A55: Farm | B55: Agrinsa | C55: Non Regional | D55: Scope 1 | E55: Monthly | F55: Diesel - Ultra Low Sulfur Diesel (ULSD) | G55: grams/liters | H55: Department for Environment Food and Rural Affairs (DEFRA) | I55: 2023 Guideline to DEFRA | J55: 2478.87 | K55: 0.30992 | L55: 33.89568 | Q55: The 2023 GHG Conversion factors are suitable for all UK based organisations, and international organisations with a UK operations footprint. Expiration Date: 7/31/2024 | R55: 2023
A56: Farm | B56: Dateland | C56: Non Regional | D56: Scope 1 | E56: Monthly | F56: Diesel - Ultra Low Sulfur Diesel (ULSD) | G56: grams/liters | H56: Department for Environment Food and Rural Affairs (DEFRA) | I56: 2023 Guideline to DEFRA | J56: 2478.87 | K56: 0.30992 | L56: 33.89568 | Q56: The 2023 GHG Conversion factors are suitable for all UK based organisations, and international organisations with a UK operations footprint. Expiration Date: 7/31/2024 | R56: 2023
A57: Food | B57: Pittsburgh, PA | C57: Non Regional | D57: Scope 1 | E57: Monthly | F57: Diesel - Ultra Low Sulfur Diesel (ULSD) | G57: grams/liters | H57: Department for Environment Food and Rural Affairs (DEFRA) | I57: 2023 Guideline to DEFRA | J57: 2478.87 | K57: 0.30992 | L57: 33.89568 | Q57: The 2023 GHG Conversion factors are suitable for all UK based organisations, and international organisations with a UK operations footprint. Expiration Date: 7/31/2024 | R57: 2023
A58: Manufacturing | B58: Carnegie, PA | C58: Non Regional | D58: Scope 1 | E58: Monthly | F58: Diesel - Ultra Low Sulfur Diesel (ULSD) | G58: grams/liters | H58: Department for Environment Food and Rural Affairs (DEFRA) | I58: 2023 Guideline to DEFRA | J58: 2478.87 | K58: 0.30992 | L58: 33.89568 | Q58: The 2023 GHG Conversion factors are suitable for all UK based organisations, and international organisations with a UK operations footprint. Expiration Date: 7/31/2024 | R58: 2023
A59: Manufacturing | B59: Chicago, IL | C59: Non Regional | D59: Scope 1 | E59: Monthly | F59: Diesel - Ultra Low Sulfur Diesel (ULSD) | G59: grams/liters | H59: Department for Environment Food and Rural Affairs (DEFRA) | I59: 2023 Guideline to DEFRA | J59: 2478.87 | K59: 0.30992 | L59: 33.89568 | Q59: The 2023 GHG Conversion factors are suitable for all UK based organisations, and international organisations with a UK operations footprint. Expiration Date: 7/31/2024 | R59: 2023
A60: Manufacturing | B60: Englewood, OH | C60: Non Regional | D60: Scope 1 | E60: Monthly | F60: Diesel - Ultra Low Sulfur Diesel (ULSD) | G60: grams/liters | H60: Department for Environment Food and Rural Affairs (DEFRA) | I60: 2023 Guideline to DEFRA | J60: 2478.87 | K60: 0.30992 | L60: 33.89568 | Q60: The 2023 GHG Conversion factors are suitable for all UK based organisations, and international organisations with a UK operations footprint. Expiration Date: 7/31/2024 | R60: 2023
A61: Manufacturing | B61: Fairfield | C61: Non Regional | D61: Scope 1 | E61: Monthly | F61: Diesel - Ultra Low Sulfur Diesel (ULSD) | G61: grams/liters | H61: Department for Environment Food and Rural Affairs (DEFRA) | I61: 2023 Guideline to DEFRA | J61: 2478.87 | K61: 0.30992 | L61: 33.89568 | Q61: The 2023 GHG Conversion factors are suitable for all UK based organisations, and international organisations with a UK operations footprint. Expiration Date: 7/31/2024 | R61: 2023
A62: Manufacturing | B62: Gurnee, IL | C62: Non Regional | D62: Scope 1 | E62: Monthly | F62: Diesel - Ultra Low Sulfur Diesel (ULSD) | G62: grams/liters | H62: Department for Environment Food and Rural Affairs (DEFRA) | I62: 2023 Guideline to DEFRA | J62: 2478.87 | K62: 0.30992 | L62: 33.89568 | Q62: The 2023 GHG Conversion factors are suitable for all UK based organisations, and international organisations with a UK operations footprint. Expiration Date: 7/31/2024 | R62: 2023
...

Sheet LB-CarbonMap
A1: Vantage Specialty Chemicals | B1: Vantage Specialty Chemicals | C1: Vantage Specialty Chemicals | D1: Vantage Specialty Chemicals | E1: Vantage Specialty Chemicals | F1: Vantage Specialty Chemicals | G1: Vantage Specialty Chemicals | H1: Vantage Specialty Chemicals | I1: Vantage Specialty Chemicals | J1: Vantage Specialty Chemicals | K1: Vantage Specialty Chemicals | L1: Vantage Specialty Chemicals | M1: Vantage Specialty Chemicals | N1: Vantage Specialty Chemicals | O1: Vantage Specialty Chemicals | P1: Vantage Specialty Chemicals | Q1: Vantage Specialty Chemicals | R1: Vantage Specialty Chemicals
A2: CarbonMap Details | B2: CarbonMap Details | C2: CarbonMap Details | D2: CarbonMap Details | E2: CarbonMap Details | F2: CarbonMap Details | G2: CarbonMap Details | H2: CarbonMap Details | I2: CarbonMap Details | J2: CarbonMap Details | K2: CarbonMap Details | L2: CarbonMap Details | M2: CarbonMap Details | N2: CarbonMap Details | O2: CarbonMap Details | P2: CarbonMap Details | Q2: CarbonMap Details | R2: CarbonMap Details
A3: Division/Group - All, Site(s) - All | B3: Division/Group - All, Site(s) - All | C3: Division/Group - All, Site(s) - All | D3: Division/Group - All, Site(s) - All | E3: Division/Group - All, Site(s) - All | F3: Division/Group - All, Site(s) - All | G3: Division/Group - All, Site(s) - All | H3: Division/Group - All, Site(s) - All | I3: Division/Group - All, Site(s) - All | J3: Division/Group - All, Site(s) - All | K3: Division/Group - All, Site(s) - All | L3: Division/Group - All, Site(s) - All | M3: Division/Group - All, Site(s) - All | N3: Division/Group - All, Site(s) - All | O3: Division/Group - All, Site(s) - All | P3: Division/Group - All, Site(s) - All | Q3: Division/Group - All, Site(s) - All | R3: Division/Group - All, Site(s) - All
A4: CarbonMap Name - Secondary: Vantage Specialty Chemicals Location-Based CM (Location-based),CarbonMap Version -CY 2023 | B4: CarbonMap Name - Secondary: Vantage Specialty Chemicals Location-Based CM (Location-based),CarbonMap Version -CY 2023 | C4: CarbonMap Name - Secondary: Vantage Specialty Chemicals Location-Based CM (Location-based),CarbonMap Version -CY 2023 | D4: CarbonMap Name - Secondary: Vantage Specialty Chemicals Location-Based CM (Location-based),CarbonMap Version -CY 2023 | E4: CarbonMap Name - Secondary: Vantage Specialty Chemicals Location-Based CM (Location-based),CarbonMap Version -CY 2023 | F4: CarbonMap Name - Secondary: Vantage Specialty Chemicals Location-Based CM (Location-based),CarbonMap Version -CY 2023 | G4: CarbonMap Name - Secondary: Vantage Specialty Chemicals Location-Based CM (Location-based),CarbonMap Version -CY 2023 | H4: CarbonMap Name - Secondary: Vantage Specialty Chemicals Location-Based CM (Location-based),CarbonMap Version -CY 2023 | I4: CarbonMap Name - Secondary: Vantage Specialty Chemicals Location-Based CM (Location-based),CarbonMap Version -CY 2023 | J4: CarbonMap Name - Secondary: Vantage Specialty Chemicals Location-Based CM (Location-based),CarbonMap Version -CY 2023 | K4: CarbonMap Name - Secondary: Vantage Specialty Chemicals Location-Based CM (Location-based),CarbonMap Version -CY 2023 | L4: CarbonMap Name - Secondary: Vantage Specialty Chemicals Location-Based CM (Location-based),CarbonMap Version -CY 2023 | M4: CarbonMap Name - Secondary: Vantage Specialty Chemicals Location-Based CM (Location-based),CarbonMap Version -CY 2023 | N4: CarbonMap Name - Secondary: Vantage Specialty Chemicals Location-Based CM (Location-based),CarbonMap Version -CY 2023 | O4: CarbonMap Name - Secondary: Vantage Specialty Chemicals Location-Based CM (Location-based),CarbonMap Version -CY 2023 | P4: CarbonMap Name - Secondary: Vantage Specialty Chemicals Location-Based CM (Location-based),CarbonMap Version -CY 2023 | Q4: CarbonMap Name - Secondary: Vantage Specialty Chemicals Location-Based CM (Location-based),CarbonMap Version -CY 2023 | R4: CarbonMap Name - Secondary: Vantage Specialty Chemicals Location-Based CM (Location-based),CarbonMap Version -CY 2023
A5: Note : all values CO2-e (The emission factors below are displayed as CO2-equivalents. Global Warming Potential (GWP) has been applied to the native pollutant emission factors.) | B5: Note : all values CO2-e (The emission factors below are displayed as CO2-equivalents. Global Warming Potential (GWP) has been applied to the native pollutant emission factors.) | C5: Note : all values CO2-e (The emission factors below are displayed as CO2-equivalents. Global Warming Potential (GWP) has been applied to the native pollutant emission factors.) | D5: Note : all values CO2-e (The emission factors below are displayed as CO2-equivalents. Global Warming Potential (GWP) has been applied to the native pollutant emission factors.) | E5: Note : all values CO2-e (The emission factors below are displayed as CO2-equivalents. Global Warming Potential (GWP) has been applied to the native pollutant emission factors.) | F5: Note : all values CO2-e (The emission factors below are displayed as CO2-equivalents. Global Warming Potential (GWP) has been applied to the native pollutant emission factors.) | G5: Note : all values CO2-e (The emission factors below are displayed as CO2-equivalents. Global Warming Potential (GWP) has been applied to the native pollutant emission factors.) | H5: Note : all values CO2-e (The emission factors below are displayed as CO2-equivalents. Global Warming Potential (GWP) has been applied to the native pollutant emission factors.) | I5: Note : all values CO2-e (The emission factors below are displayed as CO2-equivalents. Global Warming Potential (GWP) has been applied to the native pollutant emission factors.) | J5: Note : all values CO2-e (The emission factors below are displayed as CO2-equivalents. Global Warming Potential (GWP) has been applied to the native pollutant emission factors.) | K5: Note : all values CO2-e (The emission factors below are displayed as CO2-equivalents. Global Warming Potential (GWP) has been applied to the native pollutant emission factors.) | L5: Note : all values CO2-e (The emission factors below are displayed as CO2-equivalents. Global Warming Potential (GWP) has been applied to the native pollutant emission factors.) | M5: Note : all values CO2-e (The emission factors below are displayed as CO2-equivalents. Global Warming Potential (GWP) has been applied to the native pollutant emission factors.) | N5: Note : all values CO2-e (The emission factors below are displayed as CO2-equivalents. Global Warming Potential (GWP) has been applied to the native pollutant emission factors.) | O5: Note : all values CO2-e (The emission factors below are displayed as CO2-equivalents. Global Warming Potential (GWP) has been applied to the native pollutant emission factors.) | P5: Note : all values CO2-e (The emission factors below are displayed as CO2-equivalents. Global Warming Potential (GWP) has been applied to the native pollutant emission factors.) | Q5: Note : all values CO2-e (The emission factors below are displayed as CO2-equivalents. Global Warming Potential (GWP) has been applied to the native pollutant emission factors.) | R5: Note : all values CO2-e (The emission factors below are displayed as CO2-equivalents. Global Warming Potential (GWP) has been applied to the native pollutant emission factors.)
A6: Division | B6: Site | C6: Region/Utility | D6: Scope | E6: Frequency | F6: Source | G6: Units | H6: Emission Factor Set | I6: Emission Factor Version | J6: CO2 | K6: CH4 | L6: N2O | M6: HFC | N6: PFC | O6: SF6 | P6: NF3 | Q6: Comments | R6: As of Year
A7: Farm | B7: Agrinsa | C7: Non Regional | D7: Scope 1 | E7: Monthly | F7: Diesel | G7: grams/liters | H7: Department for Environment Food and Rural Affairs (DEFRA) | I7: 2023 Guideline to DEFRA | J7: 2478.87 | K7: 0.30992 | L7: 33.89568 | Q7: The 2023 GHG Conversion factors are suitable for all UK based organisations, and international organisations with a UK operations footprint. Expiration Date: 7/31/2024 | R7: 2023
A8: Farm | B8: Dateland | C8: Non Regional | D8: Scope 1 | E8: Monthly | F8: Diesel | G8: grams/liters | H8: Department for Environment Food and Rural Affairs (DEFRA) | I8: 2023 Guideline to DEFRA | J8: 2478.87 | K8: 0.30992 | L8: 33.89568 | Q8: The 2023 GHG Conversion factors are suitable for all UK based organisations, and international organisations with a UK operations footprint. Expiration Date: 7/31/2024 | R8: 2023
A9: Food | B9: Pittsburgh, PA | C9: Non Regional | D9: Scope 1 | E9: Monthly | F9: Diesel | G9: grams/liters | H9: Department for Environment Food and Rural Affairs (DEFRA) | I9: 2023 Guideline to DEFRA | J9: 2478.87 | K9: 0.30992 | L9: 33.89568 | Q9: The 2023 GHG Conversion factors are suitable for all UK based organisations, and international organisations with a UK operations footprint. Expiration Date: 7/31/2024 | R9: 2023
A10: Manufacturing | B10: Carnegie, PA | C10: Non Regional | D10: Scope 1 | E10: Monthly | F10: Diesel | G10: grams/liters | H10: Department for Environment Food and Rural Affairs (DEFRA) | I10: 2023 Guideline to DEFRA | J10: 2478.87 | K10: 0.30992 | L10: 33.89568 | Q10: The 2023 GHG Conversion factors are suitable for all UK based organisations, and international organisations with a UK operations footprint. Expiration Date: 7/31/2024 | R10: 2023
A11: Manufacturing | B11: Chicago, IL | C11: Non Regional | D11: Scope 1 | E11: Monthly | F11: Diesel | G11: grams/liters | H11: Department for Environment Food and Rural Affairs (DEFRA) | I11: 2023 Guideline to DEFRA | J11: 2478.87 | K11: 0.30992 | L11: 33.89568 | Q11: The 2023 GHG Conversion factors are suitable for all UK based organisations, and international organisations with a UK operations footprint. Expiration Date: 7/31/2024 | R11: 2023
A12: Manufacturing | B12: Englewood, OH | C12: Non Regional | D12: Scope 1 | E12: Monthly | F12: Diesel | G12: grams/liters | H12: Department for Environment Food and Rural Affairs (DEFRA) | I12: 2023 Guideline to DEFRA | J12: 2478.87 | K12: 0.30992 | L12: 33.89568 | Q12: The 2023 GHG Conversion factors are suitable for all UK based organisations, and international organisations with a UK operations footprint. Expiration Date: 7/31/2024 | R12: 2023
A13: Manufacturing | B13: Fairfield | C13: Non Regional | D13: Scope 1 | E13: Monthly | F13: Diesel | G13: grams/liters | H13: Department for Environment Food and Rural Affairs (DEFRA) | I13: 2023 Guideline to DEFRA | J13: 2478.87 | K13: 0.30992 | L13: 33.89568 | Q13: The 2023 GHG Conversion factors are suitable for all UK based organisations, and international organisations with a UK operations footprint. Expiration Date: 7/31/2024 | R13: 2023
A14: Manufacturing | B14: Gurnee, IL | C14: Non Regional | D14: Scope 1 | E14: Monthly | F14: Diesel | G14: grams/liters | H14: Department for Environment Food and Rural Affairs (DEFRA) | I14: 2023 Guideline to DEFRA | J14: 2478.87 | K14: 0.30992 | L14: 33.89568 | Q14: The 2023 GHG Conversion factors are suitable for all UK based organisations, and international organisations with a UK operations footprint. Expiration Date: 7/31/2024 | R14: 2023
A15: Manufacturing | B15: Les Borges | C15: Non Regional | D15: Scope 1 | E15: Monthly | F15: Diesel | G15: grams/liters | H15: Department for Environment Food and Rural Affairs (DEFRA) | I15: 2023 Guideline to DEFRA | J15: 2478.87 | K15: 0.30992 | L15: 33.89568 | Q15: The 2023 GHG Conversion factors are suitable for all UK based organisations, and international organisations with a UK operations footprint. Expiration Date: 7/31/2024 | R15: 2023
A16: Manufacturing | B16: Leuna | C16: Non Regional | D16: Scope 1 | E16: Monthly | F16: Diesel | G16: grams/liters | H16: Department for Environment Food and Rural Affairs (DEFRA) | I16: 2023 Guideline to DEFRA | J16: 2478.87 | K16: 0.30992 | L16: 33.89568 | Q16: The 2023 GHG Conversion factors are suitable for all UK based organisations, and international organisations with a UK operations footprint. Expiration Date: 7/31/2024 | R16: 2023
A17: Manufacturing | B17: Tucson | C17: Non Regional | D17: Scope 1 | E17: Monthly | F17: Diesel | G17: grams/liters | H17: Department for Environment Food and Rural Affairs (DEFRA) | I17: 2023 Guideline to DEFRA | J17: 2478.87 | K17: 0.30992 | L17: 33.89568 | Q17: The 2023 GHG Conversion factors are suitable for all UK based organisations, and international organisations with a UK operations footprint. Expiration Date: 7/31/2024 | R17: 2023
A18: Office | B18: Barcelona | C18: Non Regional | D18: Scope 1 | E18: Monthly | F18: Diesel | G18: grams/liters | H18: Department for Environment Food and Rural Affairs (DEFRA) | I18: 2023 Guideline to DEFRA | J18: 2478.87 | K18: 0.30992 | L18: 33.89568 | Q18: The 2023 GHG Conversion factors are suitable for all UK based organisations, and international organisations with a UK operations footprint. Expiration Date: 7/31/2024 | R18: 2023
... A30: Warehouse | B30: South Africa | C30: Non Regional | D30: Scope 1 | E30: Monthly | F30: Diesel | G30: grams/liters | H30: Department for Environment Food and Rural Affairs (DEFRA) | I30: 2023 Guideline to DEFRA | J30: 2478.87 | K30: 0.30992 | L30: 33.89568 | Q30: The 2023 GHG Conversion factors are suitable for all UK based organisations, and international organisations with a UK operations footprint. Expiration Date: 7/31/2024 | R30: 2023
A31: Farm | B31: Agrinsa | C31: - | D31: Scope 1 | E31: Monthly | F31: Diesel - Clear Diesel | G31: grams/liters | H31: Manual | I31: Manual | J31: 2478.87 | K31: 0.30992 | L31: 33.89568 | Q31: Manual Input of DEFRA Diesel EF | R31: -
A32: Farm | B32: Dateland | C32: - | D32: Scope 1 | E32: Monthly | F32: Diesel - Clear Diesel | G32: grams/liters | H32: Manual | I32: Manual | J32: 2478.87 | K32: 0.30992 | L32: 33.89568 | Q32: Manual Input of DEFRA Diesel EF | R32: -
A33: Food | B33: Pittsburgh, PA | C33: - | D33: Scope 1 | E33: Monthly | F33: Diesel - Clear Diesel | G33: grams/liters | H33: Manual | I33: Manual | J33: 2478.87 | K33: 0.30992 | L33: 33.89568 | Q33: Manual Input of DEFRA Diesel EF | R33: -
A34: Manufacturing | B34: Carnegie, PA | C34: - | D34: Scope 1 | E34: Monthly | F34: Diesel - Clear Diesel | G34: grams/liters | H34: Manual | I34: Manual | J34: 2478.87 | K34: 0.30992 | L34: 33.89568 | Q34: Manual Input of DEFRA Diesel EF | R34: -
A35: Manufacturing | B35: Chicago, IL | C35: - | D35: Scope 1 | E35: Monthly | F35: Diesel - Clear Diesel | G35: grams/liters | H35: Manual | I35: Manual | J35: 2478.87 | K35: 0.30992 | L35: 33.89568 | Q35: Manual Input of DEFRA Diesel EF | R35: -
A36: Manufacturing | B36: Englewood, OH | C36: - | D36: Scope 1 | E36: Monthly | F36: Diesel - Clear Diesel | G36: grams/liters | H36: Manual | I36: Manual | J36: 2478.87 | K36: 0.30992 | L36: 33.89568 | Q36: Manual Input of DEFRA Diesel EF | R36: -
A37: Manufacturing | B37: Fairfield | C37: - | D37: Scope 1 | E37: Monthly | F37: Diesel - Clear Diesel | G37: grams/liters | H37: Manual | I37: Manual | J37: 2478.87 | K37: 0.30992 | L37: 33.89568 | Q37: Manual Input of DEFRA Diesel EF | R37: -
A38: Manufacturing | B38: Gurnee, IL | C38: - | D38: Scope 1 | E38: Monthly | F38: Diesel - Clear Diesel | G38: grams/liters | H38: Manual | I38: Manual | J38: 2478.87 | K38: 0.30992 | L38: 33.89568 | Q38: Manual Input of DEFRA Diesel EF | R38: -
A39: Manufacturing | B39: Les Borges | C39: - | D39: Scope 1 | E39: Monthly | F39: Diesel - Clear Diesel | G39: grams/liters | H39: Manual | I39: Manual | J39: 2478.87 | K39: 0.30992 | L39: 33.89568 | Q39: Manual Input of DEFRA Diesel EF | R39: -
